Workbook

Sheet Executive Summary
A1: HOTEL BRENDLE - CASH-OUT REFINANCE REQUEST
A2: Prepared: May 04, 2026
A4: PROPERTY INFORMATION
A5: Address: | B5: 601 E Ave A, Robstown, TX 78380
A6: Property Type: | B6: Historic Hotel - Extended Stay
A7: Total Rooms: | B7: 67
A8: Currently Available: | B8: 24
A9: To Be Renovated: | B9: 43
A11: LOAN REQUEST
A12: Amount Requested: | B12: 850000
A14: USE OF PROCEEDS
A15: Existing Debt Payoff | B15: 150000
A16: Amenities & Jobsite Costs | B16: 100000
A17: Room Renovation (40 rooms @ $15k) | B17: 600000
A18: Total Uses | B18: =SUM(B15:B17) -> 850000
A20: LOAN TERMS
A21: Interest Rate: | B21: 0.075
A22: Amortization: | B22: 25 years
A23: Monthly Payment (P&I): | B23: 6281.43
A24: Annual Debt Service: | B24: =B23*12 -> 75377.16
A26: KEY METRICS (Year 3 Stabilized)
A27: Stabilized NOI: | B27: ='Annual Summary'!D6 -> 546720
A28: DSCR: | B28: ='Annual Summary'!G6 -> 1.0261492

Sheet Renovation Budget Detail
A1: RENOVATION BUDGET - LINE ITEM DETAIL
A3: LIGHT RENOVATION (7 rooms @ $1,217/room)
A4: Item | B4: Quantity | C4: Unit | D4: Unit Cost | E4: Extended | F4: Total
A5: Paint - Primer | B5: 2 | C5: gallon | D5: 35 | E5: =B5*D5 -> 70
A6: Paint - Finish | B6: 4 | C6: gallon | D6: 45 | E6: =B6*D6 -> 180
A7: Floor Sander Rental | B7: 0.33 | C7: day | D7: 90 | E7: =B7*D7 -> 29.7
A8: Floor Stain | B8: 1.5 | C8: gallon | D8: 50 | E8: =B8*D8 -> 75
A9: Polyurethane | B9: 1 | C9: gallon | D9: 60 | E9: =B9*D9 -> 60
A10: Sandpaper/Supplies | B10: 1 | C10: lot | D10: 30 | E10: =B10*D10 -> 30
A11: Drywall Sheet | B11: 1 | C11: sheet | D11: 13 | E11: =B11*D11 -> 13
A12: Joint Compound | B12: 1 | C12: bucket | D12: 18 | E12: =B12*D12 -> 18
A13: Drywall Tape/Supplies | B13: 1 | C13: lot | D13: 15 | E13: =B13*D13 -> 15
A14: Light Fixtures | B14: 2 | C14: each | D14: 40 | E14: =B14*D14 -> 80
A15: Plumbing Repair Parts | B15: 1 | C15: lot | D15: 50 | E15: =B15*D15 -> 50
A16: Door Lockset | B16: 1 | C16: each | D16: 35 | E16: =B16*D16 -> 35
A17: Materials Subtotal (per room) | E17: =SUM(E5:E16) -> 655.7 | F17: =E17*7 -> 4589.9
A19: LABOR - Light Renovation (per room)
A20: Task | B20: Hours | C20: Rate/Hr | D20: Unit Cost | E20: Extended | F20: Total
A21: Floor prep/sand/stain | B21: 8 | C21: 22 | E21: =B21*C21 -> 176
A22: Paint (prep + 2 coats) | B22: 12 | C22: 22 | E22: =B22*C22 -> 264
A23: Drywall repair | B23: 3 | C23: 22 | E23: =B23*C23 -> 66
A24: Plumbing touchup | B24: 1 | C24: 22 | E24: =B24*C24 -> 22
A25: Electrical | B25: 1 | C25: 22 | E25: =B25*C25 -> 22
A26: Install hardware | B26: 0.5 | C26: 22 | E26: =B26*C26 -> 11
A27: Labor Subtotal (per room) | E27: =SUM(E21:E26) -> 561 | F27: =E27*7 -> 3927
A29: LIGHT RENOVATION TOTAL | E29: =E17+E27 -> 1216.7 | F29: =F17+F27 -> 8516.9
A32: FULL RENOVATION (36 rooms @ $8,273/room)
A33: Item | B33: Quantity | C33: Unit | D33: Unit Cost | E33: Extended | F33: Total
A34: Drywall 4x8 Sheet | B34: 19 | C34: sheet | D34: 13 | E34: =B34*D34 -> 247
A35: Joint Compound | B35: 3 | C35: bucket | D35: 18 | E35: =B35*D35 -> 54
A36: Drywall Tape | B36: 2 | C36: roll | D36: 7 | E36: =B36*D36 -> 14
A37: Drywall Screws | B37: 1 | C37: box | D37: 15 | E37: =B37*D37 -> 15
A38: Paint - Primer | B38: 2 | C38: gallon | D38: 35 | E38: =B38*D38 -> 70
A39: Paint - Finish | B39: 4 | C39: gallon | D39: 45 | E39: =B39*D39 -> 180
A40: Floor Sander Rental | B40: 0.33 | C40: day | D40: 90 | E40: =B40*D40 -> 29.7
A41: Floor Stain | B41: 1.5 | C41: gallon | D41: 50 | E41: =B41*D41 -> 75
A42: Polyurethane | B42: 1 | C42: gallon | D42: 60 | E42: =B42*D42 -> 60
A43: Sandpaper/Supplies | B43: 1 | C43: lot | D43: 30 | E43: =B43*D43 -> 30
A44: Bathroom Wall Tile | B44: 112 | C44: sqft | D44: 3.5 | E44: =B44*D44 -> 392
A45: Bathroom Floor Tile | B45: 50 | C45: sqft | D45: 4 | E45: =B45*D45 -> 200
...

Sheet Current Operations
A1: CURRENT OPERATIONS (April 2026)
A3: OPERATING PERFORMANCE
A4: Occupied Rooms: | B4: 18
A5: Available Rooms: | B5: 24
A6: Occupancy Rate: | B6: =B4/B5 -> 0.75
A8: REVENUE
A9: Monthly Rent (Contractual): | B9: 15340
A10: Annualized Revenue: | B10: =B9*12 -> 184080
A12: OPERATING EXPENSES (Q1 2026 Average)
A13: Payroll | B13: 4792
A14: Property Taxes | B14: 3000
A15: Electric | B15: 960
A16: Gas | B16: 278
A17: Water | B17: 991
A18: Sewer | B18: 322
A19: Trash | B19: 110
A20: Consumables | B20: 1000
A21: Total Monthly Expenses: | B21: =SUM(B13:B20) -> 11453
A22: Annual Operating Expenses: | B22: =B21*12 -> 137436
A24: NET OPERATING INCOME
A25: Annual NOI: | B25: =B10-B22 -> 46644

Sheet 10-Year Monthly Projections
A1: 10-YEAR MONTHLY CASH FLOW PROJECTIONS
A3: Year | B3: Mo | C3: Rooms Avail | D3: Occ % | E3: Avg Rent | F3: Revenue | G3: Laundry Rev | H3: Total Revenue | I3: NOI | J3: Debt Svc | K3: Cash Flow | L3: DSCR
A4: 1 | B4: 1 | C4: 24 | D4: 0.5625 | E4: 852 | F4: =C4*D4*E4 -> 11502 | G4: ='Laundry Revenue'!G10 -> 464.4 | H4: =F4+G4 -> 11966.4 | I4: =F4-G4 -> 11037.6 | J4: =H4-I4 -> 928.8 | K4: =H4-I4 -> 928.8 | L4: =J4-K4 -> 0 | M4: =IF(K4=0,0,J4/K4) -> 1
A5: 1 | B5: 2 | C5: 31 | D5: 0.5625 | E5: 852 | F5: =C5*D5*E5 -> 14856.75 | G5: ='Laundry Revenue'!G11 -> 464.4 | H5: =F5+G5 -> 15321.15 | I5: =F5-G5 -> 14392.35 | J5: =H5-I5 -> 928.8 | K5: =H5-I5 -> 928.8 | L5: =J5-K5 -> 0 | M5: =IF(K5=0,0,J5/K5) -> 1
A6: 1 | B6: 3 | C6: 38 | D6: 0.5625 | E6: 852 | F6: =C6*D6*E6 -> 18211.5 | G6: ='Laundry Revenue'!G12 -> 599.85 | H6: =F6+G6 -> 18811.35 | I6: =F6-G6 -> 17611.65 | J6: =H6-I6 -> 1199.7 | K6: =H6-I6 -> 1199.7 | L6: =J6-K6 -> 0 | M6: =IF(K6=0,0,J6/K6) -> 1
A7: 1 | B7: 4 | C7: 46 | D7: 0.5625 | E7: 852 | F7: =C7*D7*E7 -> 22045.5 | G7: ='Laundry Revenue'!G13 -> 599.85 | H7: =F7+G7 -> 22645.35 | I7: =F7-G7 -> 21445.65 | J7: =H7-I7 -> 1199.7 | K7: =H7-I7 -> 1199.7 | L7: =J7-K7 -> 0 | M7: =IF(K7=0,0,J7/K7) -> 1
A8: 1 | B8: 5 | C8: 53 | D8: 0.5625 | E8: 852 | F8: =C8*D8*E8 -> 25400.25 | G8: ='Laundry Revenue'!G14 -> 599.85 | H8: =F8+G8 -> 26000.1 | I8: =F8-G8 -> 24800.4 | J8: =H8-I8 -> 1199.7 | K8: =H8-I8 -> 1199.7 | L8: =J8-K8 -> 0 | M8: =IF(K8=0,0,J8/K8) -> 1
A9: 1 | B9: 6 | C9: 60 | D9: 0.5625 | E9: 852 | F9: =C9*D9*E9 -> 28755 | G9: ='Laundry Revenue'!G15 -> 599.85 | H9: =F9+G9 -> 29354.85 | I9: =F9-G9 -> 28155.15 | J9: =H9-I9 -> 1199.7 | K9: =H9-I9 -> 1199.7 | L9: =J9-K9 -> 0 | M9: =IF(K9=0,0,J9/K9) -> 1
A10: 1 | B10: 7 | C10: 67 | D10: 0.7 | E10: 850 | F10: =C10*D10*E10 -> 39865 | G10: ='Laundry Revenue'!G16 -> 870.75 | H10: =F10+G10 -> 40735.75 | I10: =F10-G10 -> 38994.25 | J10: =H10-I10 -> 1741.5 | K10: =H10-I10 -> 1741.5 | L10: =J10-K10 -> 0 | M10: =IF(K10=0,0,J10/K10) -> 1
A11: 1 | B11: 8 | C11: 67 | D11: 0.70833 | E11: 850 | F11: =C11*D11*E11 -> 40339.393 | G11: ='Laundry Revenue'!G17 -> 967.5 | H11: =F11+G11 -> 41306.893 | I11: =F11-G11 -> 39371.893 | J11: =H11-I11 -> 1935 | K11: =H11-I11 -> 1935 | L11: =J11-K11 -> 0 | M11: =IF(K11=0,0,J11/K11) -> 1
A12: 1 | B12: 9 | C12: 67 | D12: 0.71666 | E12: 850 | F12: =C12*D12*E12 -> 40813.787 | G12: ='Laundry Revenue'!G18 -> 1161 | H12: =F12+G12 -> 41974.787 | I12: =F12-G12 -> 39652.787 | J12: =H12-I12 -> 2322 | K12: =H12-I12 -> 2322 | L12: =J12-K12 -> 0 | M12: =IF(K12=0,0,J12/K12) -> 1
A13: 1 | B13: 10 | C13: 67 | D13: 0.72499 | E13: 850 | F13: =C13*D13*E13 -> 41288.181 | G13: ='Laundry Revenue'!G19 -> 1161 | H13: =F13+G13 -> 42449.181 | I13: =F13-G13 -> 40127.181 | J13: =H13-I13 -> 2322 | K13: =H13-I13 -> 2322 | L13: =J13-K13 -> 0 | M13: =IF(K13=0,0,J13/K13) -> 1
A14: 1 | B14: 11 | C14: 67 | D14: 0.73332 | E14: 850 | F14: =C14*D14*E14 -> 41762.574 | G14: ='Laundry Revenue'!G20 -> 1161 | H14: =F14+G14 -> 42923.574 | I14: =F14-G14 -> 40601.574 | J14: =H14-I14 -> 2322 | K14: =H14-I14 -> 2322 | L14: =J14-K14 -> 0 | M14: =IF(K14=0,0,J14/K14) -> 1
A15: 1 | B15: 12 | C15: 67 | D15: 0.74165 | E15: 850 | F15: =C15*D15*E15 -> 42236.967 | G15: ='Laundry Revenue'!G21 -> 1161 | H15: =F15+G15 -> 43397.967 | I15: =F15-G15 -> 41075.967 | J15: =H15-I15 -> 2322 | K15: =H15-I15 -> 2322 | L15: =J15-K15 -> 0 | M15: =IF(K15=0,0,J15/K15) -> 1
... A123: 10 | B123: 12 | C123: 67 | D123: 0.8 | E123: 850 | F123: =C123*D123*E123 -> 45560 | G123: ='Laundry Revenue'!G129 -> 1161 | H123: =F123+G123 -> 46721 | I123: =F123-G123 -> 44399 | J123: =H123-I123 -> 2322 | K123: =H123-I123 -> 2322 | L123: =J123-K123 -> 0 | M123: =IF(K123=0,0,J123/K123) -> 1

Sheet Annual Summary
A1: ANNUAL SUMMARY & KEY METRICS
A3: Year | B3: Gross Revenue | C3: Operating Expenses | D3: NOI | E3: Debt Service | F3: Net Cash Flow | G3: DSCR | H3: Cumulative Cash Flow
A4: 1 | B4: =SUM('10-Year Monthly Projections'!H4:H15) -> 376887.35 | C4: =SUM('10-Year Monthly Projections'!G4:G15) -> 9810.45 | D4: =B4-C4 -> 367076.9 | E4: =SUM('10-Year Monthly Projections'!I4:I15) -> 357266.45 | F4: =D4-E4 -> 9810.45 | G4: =IF(E4=0,0,D4/E4) -> 1.0274598 | H4: =F4 -> 9810.45
A5: 2 | B5: =SUM('10-Year Monthly Projections'!H16:H27) -> 550676.07 | C5: =SUM('10-Year Monthly Projections'!G16:G27) -> 13932 | D5: =B5-C5 -> 536744.07 | E5: =SUM('10-Year Monthly Projections'!I16:I27) -> 522812.07 | F5: =D5-E5 -> 13932 | G5: =IF(E5=0,0,D5/E5) -> 1.0266482 | H5: =H4+F5 -> 23742.45
A6: 3 | B6: =SUM('10-Year Monthly Projections'!H28:H39) -> 560652 | C6: =SUM('10-Year Monthly Projections'!G28:G39) -> 13932 | D6: =B6-C6 -> 546720 | E6: =SUM('10-Year Monthly Projections'!I28:I39) -> 532788 | F6: =D6-E6 -> 13932 | G6: =IF(E6=0,0,D6/E6) -> 1.0261492 | H6: =H5+F6 -> 37674.45
A7: 4 | B7: =SUM('10-Year Monthly Projections'!H40:H51) -> 560652 | C7: =SUM('10-Year Monthly Projections'!G40:G51) -> 13932 | D7: =B7-C7 -> 546720 | E7: =SUM('10-Year Monthly Projections'!I40:I51) -> 532788 | F7: =D7-E7 -> 13932 | G7: =IF(E7=0,0,D7/E7) -> 1.0261492 | H7: =H6+F7 -> 51606.45
A8: 5 | B8: =SUM('10-Year Monthly Projections'!H52:H63) -> 560652 | C8: =SUM('10-Year Monthly Projections'!G52:G63) -> 13932 | D8: =B8-C8 -> 546720 | E8: =SUM('10-Year Monthly Projections'!I52:I63) -> 532788 | F8: =D8-E8 -> 13932 | G8: =IF(E8=0,0,D8/E8) -> 1.0261492 | H8: =H7+F8 -> 65538.45
A9: 6 | B9: =SUM('10-Year Monthly Projections'!H64:H75) -> 560652 | C9: =SUM('10-Year Monthly Projections'!G64:G75) -> 13932 | D9: =B9-C9 -> 546720 | E9: =SUM('10-Year Monthly Projections'!I64:I75) -> 532788 | F9: =D9-E9 -> 13932 | G9: =IF(E9=0,0,D9/E9) -> 1.0261492 | H9: =H8+F9 -> 79470.45
A10: 7 | B10: =SUM('10-Year Monthly Projections'!H76:H87) -> 560652 | C10: =SUM('10-Year Monthly Projections'!G76:G87) -> 13932 | D10: =B10-C10 -> 546720 | E10: =SUM('10-Year Monthly Projections'!I76:I87) -> 532788 | F10: =D10-E10 -> 13932 | G10: =IF(E10=0,0,D10/E10) -> 1.0261492 | H10: =H9+F10 -> 93402.45
A11: 8 | B11: =SUM('10-Year Monthly Projections'!H88:H99) -> 560652 | C11: =SUM('10-Year Monthly Projections'!G88:G99) -> 13932 | D11: =B11-C11 -> 546720 | E11: =SUM('10-Year Monthly Projections'!I88:I99) -> 532788 | F11: =D11-E11 -> 13932 | G11: =IF(E11=0,0,D11/E11) -> 1.0261492 | H11: =H10+F11 -> 107334.45
A12: 9 | B12: =SUM('10-Year Monthly Projections'!H100:H111) -> 560652 | C12: =SUM('10-Year Monthly Projections'!G100:G111) -> 13932 | D12: =B12-C12 -> 546720 | E12: =SUM('10-Year Monthly Projections'!I100:I111) -> 532788 | F12: =D12-E12 -> 13932 | G12: =IF(E12=0,0,D12/E12) -> 1.0261492 | H12: =H11+F12 -> 121266.45
A13: 10 | B13: =SUM('10-Year Monthly Projections'!H112:H123) -> 560652 | C13: =SUM('10-Year Monthly Projections'!G112:G123) -> 13932 | D13: =B13-C13 -> 546720 | E13: =SUM('10-Year Monthly Projections'!I112:I123) -> 532788 | F13: =D13-E13 -> 13932 | G13: =IF(E13=0,0,D13/E13) -> 1.0261492 | H13: =H12+F13 -> 135198.45

Sheet Sources & Uses
A1: SOURCES & USES OF FUNDS
A3: SOURCES
A4: New Loan Proceeds | B4: 850000
A5: TOTAL SOURCES | B5: =B4 -> 850000
A7: USES
A8: Existing Debt Payoff | B8: ='Renovation Budget Detail'!E156 -> 450234.1
A9: Room Renovation (40 rooms @ $15k) | B9: 600000
A10: Room Renovation (43 rooms) | B10: ='Renovation Budget Detail'!E$13 -> 15
A11: Jobsite Costs & Contingency | B11: 25000
A12: TOTAL USES | B12: =SUM(B8:B11) -> 1075249.1
A14: Note: 40% renovation grant potential ($240k) available but not assumed in projections

Sheet Debt Service Schedule
A1: DEBT SERVICE SCHEDULE (First 10 Years)
A2: Loan: $850,000 @ 7.5% for 25 years
A4: Year | B4: Month | C4: Payment | D4: Interest | E4: Principal | F4: Balance
A5: 1 | B5: 1 | C5: 6281.43 | D5: 5312.5 | E5: 968.93 | F5: 849031.07
A6: 1 | B6: 2 | C6: 6281.43 | D6: 5306.4442 | E6: 974.98581 | F6: 848056.08
A7: 1 | B7: 3 | C7: 6281.43 | D7: 5300.3505 | E7: 981.07947 | F7: 847075
A8: 1 | B8: 4 | C8: 6281.43 | D8: 5294.2188 | E8: 987.21122 | F8: 846087.79
A9: 1 | B9: 5 | C9: 6281.43 | D9: 5288.0487 | E9: 993.38129 | F9: 845094.41
A10: 1 | B10: 6 | C10: 6281.43 | D10: 5281.8401 | E10: 999.58992 | F10: 844094.82
A11: 1 | B11: 7 | C11: 6281.43 | D11: 5275.5926 | E11: 1005.8374 | F11: 843088.98
A12: 1 | B12: 8 | C12: 6281.43 | D12: 5269.3062 | E12: 1012.1238 | F12: 842076.86
A13: 1 | B13: 9 | C13: 6281.43 | D13: 5262.9804 | E13: 1018.4496 | F13: 841058.41
A14: 1 | B14: 10 | C14: 6281.43 | D14: 5256.6151 | E14: 1024.8149 | F14: 840033.6
A15: 1 | B15: 11 | C15: 6281.43 | D15: 5250.21 | E15: 1031.22 | F15: 839002.38
A16: 1 | B16: 12 | C16: 6281.43 | D16: 5243.7649 | E16: 1037.6651 | F16: 837964.71
... A124: 10 | B124: 12 | C124: 6281.43 | D124: 4247.698 | E124: 2033.732 | F124: 677597.95

Sheet Property Valuation
A1: PROPERTY VALUATION ANALYSIS
A3: CURRENT VALUE (AS-IS)
A4: Current NOI: | B4: ='Current Operations'!B25 -> 46644
A5: Capitalization Rate: | B5: 0.12
A6: Current Value: | B6: =B4/B5 -> 388700
A8: STABILIZED VALUE (Post-Renovation, Year 3)
A9: Stabilized NOI: | B9: ='Annual Summary'!D6 -> 546720
A10: Capitalization Rate: | B10: 0.1
A11: Stabilized Value: | B11: =B9/B10 -> 5467200
A13: LOAN METRICS
A14: Loan Amount: | B14: 850000
A15: Stabilized Value: | B15: =B11 -> 5467200
A16: Loan-to-Value (LTV): | B16: =B14/B15 -> 0.15547264
A17: Equity Position: | B17: =B15-B14 -> 4617200

Sheet Laundry Revenue
A1: LAUNDRY REVENUE PROJECTIONS (120 Months)
A3: ASSUMPTIONS:
A4: Loads per occupied room per week: | B4: 1
A5: Washer price per load: | B5: 2.5
A6: Dryer price per load: | B6: 2
A7: Total per load: | B7: =B5+B6 -> 4.5
A9: Year | B9: Month | C9: Occupied Rooms | D9: Weekly Loads | E9: Monthly Loads | F9: Price/Load | G9: Monthly Revenue
A10: 1 | B10: 1 | C10: 24 | D10: =C11*$B$4 -> 24 | E10: =D10*4.3 -> 103.2 | F10: =$B$7 -> 4.5 | G10: =E10*F10 -> 464.4
A11: 1 | B11: 2 | C11: 24 | D11: =C11*$B$4 -> 24 | E11: =D11*4.3 -> 103.2 | F11: =$B$7 -> 4.5 | G11: =E11*F11 -> 464.4
A12: 1 | B12: 3 | C12: 31 | D12: =C12*$B$4 -> 31 | E12: =D12*4.3 -> 133.3 | F12: =$B$7 -> 4.5 | G12: =E12*F12 -> 599.85
A13: 1 | B13: 4 | C13: 31 | D13: =C13*$B$4 -> 31 | E13: =D13*4.3 -> 133.3 | F13: =$B$7 -> 4.5 | G13: =E13*F13 -> 599.85
A14: 1 | B14: 5 | C14: 31 | D14: =C14*$B$4 -> 31 | E14: =D14*4.3 -> 133.3 | F14: =$B$7 -> 4.5 | G14: =E14*F14 -> 599.85
A15: 1 | B15: 6 | C15: 31 | D15: =C15*$B$4 -> 31 | E15: =D15*4.3 -> 133.3 | F15: =$B$7 -> 4.5 | G15: =E15*F15 -> 599.85
A16: 1 | B16: 7 | C16: 45 | D16: =C16*$B$4 -> 45 | E16: =D16*4.3 -> 193.5 | F16: =$B$7 -> 4.5 | G16: =E16*F16 -> 870.75
A17: 1 | B17: 8 | C17: 50 | D17: =C17*$B$4 -> 50 | E17: =D17*4.3 -> 215 | F17: =$B$7 -> 4.5 | G17: =E17*F17 -> 967.5
A18: 1 | B18: 9 | C18: 60 | D18: =C18*$B$4 -> 60 | E18: =D18*4.3 -> 258 | F18: =$B$7 -> 4.5 | G18: =E18*F18 -> 1161
A19: 1 | B19: 10 | C19: 60 | D19: =C19*$B$4 -> 60 | E19: =D19*4.3 -> 258 | F19: =$B$7 -> 4.5 | G19: =E19*F19 -> 1161
A20: 1 | B20: 11 | C20: 60 | D20: =C20*$B$4 -> 60 | E20: =D20*4.3 -> 258 | F20: =$B$7 -> 4.5 | G20: =E20*F20 -> 1161
A21: 1 | B21: 12 | C21: 60 | D21: =C21*$B$4 -> 60 | E21: =D21*4.3 -> 258 | F21: =$B$7 -> 4.5 | G21: =E21*F21 -> 1161
A22: 2 | B22: 1 | C22: 60 | D22: =C22*$B$4 -> 60 | E22: =D22*4.3 -> 258 | F22: =$B$7 -> 4.5 | G22: =E22*F22 -> 1161
... A129: 10 | B129: 12 | C129: 60 | D129: =C129*$B$4 -> 60 | E129: =D129*4.3 -> 258 | F129: =$B$7 -> 4.5 | G129: =E129*F129 -> 1161
