Workbook
Name Annual_interest_rate: #REF!
Name Annual_interest_rate: #REF!
Name Beg.Bal: IF(#REF!<>"",#REF!,"")
Name Beg.Bal: IF(#REF!<>"",#REF!,"")
Name buildable: #REF!
Name buildable: #REF!
Name Business_License: #REF!
Name Business_License: #REF!
Name Car_Damages: #REF!
Name Car_Damages: #REF!
Name CITY: [1]OFCPRELM!$B$13
Name Copy_Printing: #REF!
Name Copy_Printing: #REF!
Name Coupon_Sales: #REF!
Name Coupon_Sales: #REF!
Name Credit_Card: #REF!
Name Credit_Card: #REF!
Name Cum.Interest: IF(#REF!<>"",#REF!+#REF!,"")
Name Cum.Interest: IF(#REF!<>"",#REF!+#REF!,"")
Name Customer_Service: #REF!
Name Customer_Service: #REF!
Name ddd: IF(OR(#REF!="",#REF!='Table 1.5'!Total_payments),"",#REF!+1)
Name ddd: IF(OR(#REF!="",#REF!='Table 1A'!Total_payments),"",#REF!+1)
Name ddd: IF(OR(#REF!="",#REF!='Table 3.0'!Total_payments),"",#REF!+1)
Name ddd: IF(OR(#REF!="",#REF!=Total_payments),"",#REF!+1)
Name Degreasing: #REF!
Name Degreasing: #REF!
Name Electricity: #REF!
Name Electricity: #REF!
Name Ending.Balance: IF(#REF!<>"",#REF!-#REF!,"")
Name Ending.Balance: IF(#REF!<>"",#REF!-#REF!,"")
Name Equipment_Repairs: #REF!
Name Equipment_Repairs: #REF!
Name Fire_Protection: #REF!
Name Fire_Protection: #REF!
Name First_payment_due: #REF!
Name First_payment_due: #REF!
Name Incentive_Fee: #REF!
Name Incentive_Fee: #REF!
Name Interest: IF(#REF!<>"",#REF!*'Table 1.1'!Periodic_rate,"")
Name Interest: IF(#REF!<>"",#REF!*'Table 1.2'!Periodic_rate,"")
Name Interest: IF(#REF!<>"",#REF!*'Table 1.5'!Periodic_rate,"")
Name Interest: IF(#REF!<>"",#REF!*'Table 1A'!Periodic_rate,"")
Name Interest: IF(#REF!<>"",#REF!*'Table 3.0'!Periodic_rate,"")
Name Interest: IF(#REF!<>"",#REF!*Periodic_rate,"")
Name Janitorial: #REF!
Name Janitorial: #REF!
Name Key_Card_Sales: #REF!
Name Key_Card_Sales: #REF!
Name Keys: #REF!
Name Keys: #REF!
Name Lamping: #REF!
Name Lamping: #REF!
Name Last_Row: IF(Values_Entered,Header_Row+Number_of_Payments,Header_Row)
Name Liability_Insurance: #REF!
Name Liability_Insurance: #REF!
Name Management_Fee: #REF!
Name Management_Fee: #REF!
Name Mileage: #REF!
Name Mileage: #REF!

Sheet Table 1A
A1: TABLE 1A - INPUT ASSUMPTIONS - | D1: TUCSON AIRPORT CENTER
A3: General Assumptions | E3: Rollover Leasing Assumptions | F3: Standard | G3: Basement | H3: US Orthopedics | I3: Warehouse (24,000 Sq.Ft.)
A4: Analysis Start | C4: 38534 | E4: Renewal Probability | F4: 0.75 | G4: 0.7 | H4: 0.8 | I4: 0.75
A5: Total Net Rentable Area | C5: 129097 | E5: Market Rent New ($ per Sq.Ft./Mos/NNN) | F5: 0.55 | G5: 15 | H5: 27 | I5: 0.4
A6: Market Rent Growth (%) | C6: 0.03 | E6: Market Rent Renewal ($ per Sq.Ft./Mos/NNN) | F6: 0.55 | G6: 17 | H6: 27 | I6: 0.4
A7: Expense Growth | C7: 0.03 | E7: Months Vacant | F7: 6 | G7: 9 | H7: 9 | I7: 9
A8: Operating Expenses ($/Sq. Ft.) | C8: 2.5163482 | E8: Tenant Improvements
A9: Deferred Maintenance | C9: 1000000 | E9: New | F9: 8 | G9: 20 | H9: 20 | I9: 4
A10: Capital Reserves ($/Sq. Ft.) | C10: 0.1545 | E10: Renewal | F10: 2 | G10: 10 | H10: 10 | I10: 0
A11: Closing Costs (B) | C11: =#REF! -> #REF! | E11: Leasing Commissions
A12: Vacancy Loss | C12: 0.1 | E12: New | F12: 0.06 | G12: 0.08 | H12: 0.08 | I12: 0.06
A13: Occupancy | C13: 0.42 | E13: Renewal | F13: 0.03 | G13: 0.03 | H13: 0.03 | I13: 0.03
A14: Leased Up By | C14: 39326 | E14: Rent Abatements | F14: 0 | G14: 3 | H14: 3 | I14: 0
A15: Acquisition Commission (A) | C15: =3%*F20 -> 132000 | E15: Annual Rent Increases | F15: 0.03 | G15: 0 | H15: 0 | I15: 0.03
E16: Lease Term | F16: 5 yrs | G16: 3 | H16: 5 | I16: 5 yrs
A17: Debt Assumptions- Alliance Bank | E17: Lease Type | F17: NNN | G17: Base Year | H17: Base Year | I17: NNN
A18: Loan Amount | C18: 3600000
A19: Cap-Ex, TI & LC Holdback | C19: =450000+475000+125000 -> 1050000 | E19: Pricing
A20: Initial Funding | C20: =C18-C19 -> 2550000 | E20: Asking Price | F20: 4400000
A21: LTV | C21: =C20/F20 -> 0.57954545 | E21: Cap Rate | F21: 0.046780909
A22: Amortization (months) | C22: Interest Only | E22: Table 3.0 | F22: 4400000
A23: Interest Rate- Acquisition | C23: 6.23% Fixed | E23: Cap Rate (on Yr 1 Proforma) | F23: 0.061696364
A24: Interest Rate- Cap-Ex, TI & LC Draws | C24: Prime + 1% (Est. 7.5% Yr 1)
A25: Points and Fees | C25: 36000 | E25: Detailed Closing Costs
A26: Prepayment Penalty | C26: 1% in year 1 then $0 | E26: Commission (Acquisition) | F26: 132000 | H26: 132000
A27: Term (years/mos) | C27: 2 years | E27: Due Diligence and Legal | F27: =F29-F26-F28 -> #REF! | H27: 94730
E28: Loan Fees | F28: 36000
A29: Debt Assumptions- Refinance | E29: Total Est. Closing Costs | F29: =C11 -> #REF! | H29: 250200
A30: Loan Amount | C30: 5500000
A31: TI & LC Holdback | C31: 0
A32: Initial Funding | C32: =C30-C31 -> 5500000 | E32: (A)- Included in Closing Costs
A33: LTV | C33: 0.7 | E33: (B)- See Detailed Closing Costs Above
A34: Amortization (months) | C34: 300
A35: Interest Rate | C35: 0.07
A36: Points and Fees | C36: 0.01
A37: Term (years/mos) | C37: 10

Sheet Table 1.0
A1: TABLE 1.0 - TUCSON AIRPORT CENTER- EXISTING RENT ROLL AS OF MAY 31, 2005
A4: TENANT | B4: SUITE | C4: SF | D4: BASE | E4: $/SF | F4: $/SF | G4: LEASE | H4: EXP. REIMB. | I4: $/YR | J4: TOTAL | K4: $/SF/YR | L4: $/SF/MO | M4: LEASE | N4: LEASE | O4: INCREASES | Q4: NOTES
B5: # | D5: RENT/YR | E5: /YR | F5: /MO | G5: TYPE | H5: SF/YR (B) | J5: REVENUES | M5: START | N5: EXPIRES | O5: ($/SF/YR)
S7: =S11/12 -> 0.95833333
A8: Qantas Airways | B8: 1 | C8: 19204 | D8: 154526 | E8: =D8/C8 -> 8.0465528 | F8: =E8/12 -> 0.67054607 | G8: Net (C) | H8: 2.52 | I8: =H8*C8 -> 48394.08 | J8: =I8+D8 -> 202920.08 | K8: =IF(C8=0,0,J8/C8) -> 10.566553 | L8: =K8/12 -> 0.88054607 | M8: 37653 | N8: 39600 | O8: 2.5% Bumps | Q8: See (C) below. | S8: =E8*1.15 -> 9.2535357 | T8: =S8*1.15 -> 10.641566 | U8: =T8*1.15 -> 12.237801 | V8: =U8*1.15 -> 14.073471
A9: Davis Select | B9: 2 | C9: 12512 | D9: 64562 | E9: =D9/C9 -> 5.1600064 | F9: =E9/12 -> 0.43000053 | G9: Net | H9: 2.52 | I9: =H9*C9 -> 31530.24 | J9: =I9+D9 -> 96092.24 | K9: =IF(C9=0,0,J9/C9) -> 7.6800064 | M9: 37773 | N9: 39692 | O9: 2.5% Bumps
A10: Davis Select (Expansion Space) | B10: 2a | C10: 7488 | D10: 41334 | E10: =D10/C10 -> 5.5200321 | F10: =E10/12 -> 0.46000267 | G10: Net | H10: 2.52 | I10: =H10*C10 -> 18869.76 | J10: =I10+D10 -> 60203.76 | K10: =IF(C10=0,0,J10/C10) -> 8.0400321 | L10: =K10/12 -> 0.67000267 | M10: 38412 | N10: 39692 | O10: 2.5% Bumps | S10: 12.93 | T10: 14.22
A11: APEX | B11: =B35 -> 0 | C11: 15000 | D11: 95400 | E11: =D11/C11 -> 6.36 | F11: =E11/12 -> 0.53 | G11: Net | H11: 2.52 | I11: =H11*C11 -> 37800 | J11: =I11+D11 -> 133200 | K11: =IF(C11=0,0,J11/C11) -> 8.88 | L11: =K11/12 -> 0.74 | M11: 37803 | N11: 39630 | O11: 2.5% Bumps | S11: =10*1.15 -> 11.5
A12: Iron Mountain Temp. Space | B12: 2B | C12: 24000 | D12: =C12*E12 -> 115200 | E12: =F12*12 -> 4.8 | F12: 0.4 | G12: Net | H12: 2.52 | I12: =H12*C12 -> 60480 | J12: =I12+D12 -> 175680 | K12: =IF(C12=0,0,J12/C12) -> 7.32 | M12: 38443 | N12: 38596 | O12: None | Q12: Temp. Lease for Storage
A13: Building C Ste 1 (VACANT) | B13: C1 | C13: 7500
A14: Building C Ste 2 (VACANT) | B14: C2 | C14: 7500
A15: Building A Ste 1 (VACANT) | B15: A1 | C15: 12000
A16: Building A Ste 2 (VACANT) | B16: A2 | C16: 12000
A17: Building A Ste 3 (VACANT) | B17: A3 | C17: 11893
A20: Totals | C20: =SUM(C8:C19) -> 129097 | D20: =SUM(D8:D12) -> 471022 | E20: =D20/(C21) -> 6.0229912 | F20: =ROUND(E20/12,2) -> 0.5 | H20: =I20/C21 -> 2.52 | I20: =SUM(I8:I17) -> 197074.08 | J20: =I20+D20 -> 668096.08 | K20: =J20/C21 -> 8.5429912 | L20: =K20/12 -> 0.71191593
A21: Total Space Occupied | C21: =SUM(C8:C12) -> 78204
A22: % Occupied | C22: =(C21-C12)/C20 -> 0.41987033 | D22: (A)
A23: Avg. Rent of Occupied Space | C23: =(D20-D12)/(C21-C12) -> 6.5644971 | D23: /SF/YR (A)
A25: (A) Excludes Iron Mountain Temporary Space
A26: (B) NNN tenants pay pro-rata share of operating expenses.
A27: (C) QANTAS Airways' actual lease rate is modified gross. Qantas lease rate converted to NNN for comparison purposes. The actual lease rate is $10.56/sq.ft./Yr. with expense reimbursements over 2003 base year.
A54: =A33 -> 0 | B54: 1 | C54: 3600
A55: =A34 -> 0 | B55: 2 | C55: 1200
A56: =A35 -> 0 | B56: 3 | C56: 1200
A57: =A36 -> 0 | B57: 4 | C57: 1500
A58: =A37 -> 0 | B58: 5 | C58: 1500
A59: =A38 -> 0 | B59: 6 | C59: 1500
A60: =A39 -> 0 | B60: 7 | C60: 1500
A61: =A40 -> 0 | B61: 8 | C61: 1200
A62: =A41 -> 0 | B62: 9 | C62: 1200
A63: =A42 -> 0 | B63: 10 | C63: 1200
A64: =A43 -> 0 | B64: 11 | C64: 1200
C66: =SUM(C54:C64) -> 16800

Sheet Table 1.1
A1: TABLE 1.1 -TUCSON AIRPORT CENTER - GROSS POTENTIAL RENT PER SQUARE FOOT (1)
C3: Market Rents | D3: Yr 1 | E3: Yr 2 | F3: Yr 3 | G3: Yr 4 | H3: Yr 5 | I3: Yr 6 | J3: Yr 7 | K3: Yr 8 | L3: Yr 9
C4: Standard | D4: =0.55*12 -> 6.6 | E4: =D4*1.03 -> 6.798 | F4: =E4*1.03 -> 7.00194 | G4: =F4*1.03 -> 7.2119982 | H4: =G4*1.03 -> 7.4283581 | I4: =H4*1.03 -> 7.6512089 | J4: =I4*1.03 -> 7.8807452 | K4: =J4*1.03 -> 8.1171675 | L4: =K4*1.03 -> 8.3606825
C5: Warehouse | D5: =0.4*12 -> 4.8 | E5: =D5*1.03 -> 4.944 | F5: =E5*1.03 -> 5.09232 | G5: =F5*1.03 -> 5.2450896 | H5: =G5*1.03 -> 5.4024423 | I5: =H5*1.03 -> 5.5645156 | J5: =I5*1.03 -> 5.731451 | K5: =J5*1.03 -> 5.9033946 | L5: =K5*1.03 -> 6.0804964
C6: Fiscal Year Ending | D6: 38869 | E6: 39234 | F6: 39600 | G6: 39965 | H6: 40330 | I6: 40695 | J6: 41061 | K6: 41426 | L6: 41791
A7: Rental Rates - $/SF | B7: Suite | C7: SF | D7: Yr 1 | E7: Yr 2 | F7: Yr 3 | G7: Yr 4 | H7: Yr 5 | I7: Yr 6 | J7: Yr 7 | K7: Yr 8 | L7: Yr 9 | N7: TENANT | O7: SUITE
N8: Qantas Airways | O8: 2801 | P8: 203370 | Q8: 210092 | R8: 214317 | S8: 138500 | T8: 142308 | U8: 146577 | V8: 150974 | W8: 155504 | X8: 160169 | Y8: 164573
A9: ='Table 1.0'!A8 -> Qantas Airways | B9: ='Table 1.0'!B8 -> 1 | C9: ='Table 1.0'!C8 -> 19204 | D9: =IF($C9,P8/$C9,0)-P23 -> 8.0736331 | E9: =IF($C9,Q8/$C9,0)-Q23 -> 8.2478973 | F9: =IF($C9,R8/$C9,0)-R23 -> 8.3551511 | G9: =IF($C9,S8/$C9,0) -> 7.2120392 | H9: =IF($C9,T8/$C9,0) -> 7.4103312 | I9: =IF($C9,U8/$C9,0) -> 7.6326286 | J9: =IF($C9,V8/$C9,0) -> 7.8615913 | K9: =IF($C9,W8/$C9,0) -> 8.0974797 | L9: =IF($C9,X8/$C9,0) -> 8.3403978 | N9: Davis Select | O9: 2949A | P9: 69692 | Q9: 71193 | R9: 73320 | S9: 86446 | T9: 92041 | U9: 94802 | V9: 97647 | W9: 100576 | X9: 103593 | Y9: 106440
A10: ='Table 1.0'!A9 -> Davis Select | B10: ='Table 1.0'!B9 -> 2 | C10: ='Table 1.0'!C9 -> 12512 | D10: =IF($C10,P9/$C10,0) -> 5.5700128 | E10: =IF($C10,Q9/$C10,0) -> 5.6899776 | F10: =IF($C10,R9/$C10,0) -> 5.8599744 | G10: =IF($C10,S9/$C10,0) -> 6.9090473 | H10: =IF($C10,T9/$C10,0) -> 7.356218 | I10: =IF($C10,U9/$C10,0) -> 7.5768862 | J10: =IF($C10,V9/$C10,0) -> 7.8042679 | K10: =IF($C10,W9/$C10,0) -> 8.0383632 | L10: =IF($C10,X9/$C10,0) -> 8.2794917 | N10: Davis Expansion Space | O10: 2949 A | P10: 41708 | Q10: 42607 | R10: 43880 | S10: 51734 | T10: 55084 | U10: 56736 | V10: 58438 | W10: 60191 | X10: 61997 | Y10: 63700
A11: ='Table 1.0'!A10 -> Davis Select (Expansion Space) | B11: ='Table 1.0'!B10 -> 2a | C11: ='Table 1.0'!C10 -> 7488 | D11: =IF($C11,P10/$C11,0) -> 5.5699786 | E11: =IF($C11,Q10/$C11,0) -> 5.6900374 | F11: =IF($C11,R10/$C11,0) -> 5.8600427 | G11: =IF($C11,S10/$C11,0) -> 6.9089209 | H11: =IF($C11,T10/$C11,0) -> 7.3563034 | I11: =IF($C11,U10/$C11,0) -> 7.5769231 | J11: =IF($C11,V10/$C11,0) -> 7.8042201 | K11: =IF($C11,W10/$C11,0) -> 8.038328 | L11: =IF($C11,X10/$C11,0) -> 8.2795139 | N11: APEX | O11: 15000 | P11: 95400 | Q11: 99000 | R11: 100800 | S11: 107565 | T11: 110884 | U11: 114211 | V11: 117637 | W11: 121166 | X11: 124802 | Y11: 128232
A12: ='Table 1.0'!A11 -> APEX | B12: ='Table 1.0'!B11 -> 0 | C12: ='Table 1.0'!C11 -> 15000 | D12: =IF($C12,P11/$C12,0) -> 6.36 | E12: =IF($C12,Q11/$C12,0) -> 6.6 | F12: =IF($C12,R11/$C12,0) -> 6.72 | G12: =IF($C12,S11/$C12,0) -> 7.171 | H12: =IF($C12,T11/$C12,0) -> 7.3922667 | I12: =IF($C12,U11/$C12,0) -> 7.6140667 | J12: =IF($C12,V11/$C12,0) -> 7.8424667 | K12: =IF($C12,W11/$C12,0) -> 8.0777333 | L12: =IF($C12,X11/$C12,0) -> 8.3201333 | N12: Iron Mountain | O12: Bldg E | P12: 115200 | Q12: 118656 | R12: 122216 | S12: 125882 | T12: 129659 | U12: 133548 | V12: 137555 | W12: 140994 | X12: 145224 | Y12: 149580
A13: Iron Mountain Temp. Space (A) | B13: ='Table 1.0'!B12 -> 2B | C13: ='Table 1.0'!C12 -> 24000 | D13: =IF($C13,P12/$C13,0) -> 4.8 | E13: =IF($C13,Q12/$C13,0) -> 4.944 | F13: =IF($C13,R12/$C13,0) -> 5.0923333 | G13: =IF($C13,S12/$C13,0) -> 5.2450833 | H13: =IF($C13,T12/$C13,0) -> 5.4024583 | I13: =IF($C13,U12/$C13,0) -> 5.5645 | J13: =IF($C13,V12/$C13,0) -> 5.7314583 | K13: =IF($C13,W12/$C13,0) -> 5.87475 | L13: =IF($C13,X12/$C13,0) -> 6.051 | N13: Building C- Suite 1 | O13: Mo 8 | P13: 49500 | Q13: 49624 | R13: 51112 | S13: 52646 | T13: 54225 | U13: 55852 | V13: 59106 | W13: 60879 | X13: 62705 | Y13: 64586
A14: ='Table 1.0'!A13 -> Building C Ste 1 (VACANT) | B14: ='Table 1.0'!B13 -> C1 | C14: ='Table 1.0'!C13 -> 7500 | D14: =IF($C14,P13/$C14,0) -> 6.6 | E14: =IF($C14,Q13/$C14,0) -> 6.6165333 | F14: =IF($C14,R13/$C14,0) -> 6.8149333 | G14: =IF($C14,S13/$C14,0) -> 7.0194667 | H14: =IF($C14,T13/$C14,0) -> 7.23 | I14: =IF($C14,U13/$C14,0) -> 7.4469333 | J14: =IF($C14,V13/$C14,0) -> 7.8808 | K14: =IF($C14,W13/$C14,0) -> 8.1172 | L14: =IF($C14,X13/$C14,0) -> 8.3606667 | N14: Building C- Suite 2 | O14: Mo 10 | P14: 49500 | Q14: 50119 | R14: 50366 | S14: 51877 | T14: 53434 | U14: 55037 | V14: 57691 | W14: 59992 | X14: 61792 | Y14: 63646
A15: ='Table 1.0'!A14 -> Building C Ste 2 (VACANT) | B15: ='Table 1.0'!B14 -> C2 | C15: ='Table 1.0'!C14 -> 7500 | D15: =IF($C15,P14/$C15,0) -> 6.6 | E15: =IF($C15,Q14/$C15,0) -> 6.6825333 | F15: =IF($C15,R14/$C15,0) -> 6.7154667 | G15: =IF($C15,S14/$C15,0) -> 6.9169333 | H15: =IF($C15,T14/$C15,0) -> 7.1245333 | I15: =IF($C15,U14/$C15,0) -> 7.3382667 | J15: =IF($C15,V14/$C15,0) -> 7.6921333 | K15: =IF($C15,W14/$C15,0) -> 7.9989333 | L15: =IF($C15,X14/$C15,0) -> 8.2389333 | N15: Bldg A Suite 1 | O15: Mo 5 | P15: 64800 | Q15: 65772 | R15: 67745 | S15: 69778 | T15: 71871 | U15: 74027 | V15: 75872 | W15: 78148 | X15: 80493 | Y15: 82908
A16: ='Table 1.0'!A15 -> Building A Ste 1 (VACANT) | B16: ='Table 1.0'!B15 -> A1 | C16: ='Table 1.0'!C15 -> 12000 | D16: =IF($C16,P15/$C16,0) -> 5.4 | E16: =IF($C16,Q15/$C16,0) -> 5.481 | F16: =IF($C16,R15/$C16,0) -> 5.6454167 | G16: =IF($C16,S15/$C16,0) -> 5.8148333 | H16: =IF($C16,T15/$C16,0) -> 5.98925 | I16: =IF($C16,U15/$C16,0) -> 6.1689167 | J16: =IF($C16,V15/$C16,0) -> 6.3226667 | K16: =IF($C16,W15/$C16,0) -> 6.5123333 | L16: =IF($C16,X15/$C16,0) -> 6.70775 | N16: Bldg A Suite 2 | O16: Mo 12 | P16: 79200 | Q16: 80982 | R16: 79794 | S16: 82188 | T16: 84653 | U16: 87193 | V16: 90498 | W16: 95042 | X16: 97893 | Y16: 100830
A17: ='Table 1.0'!A16 -> Building A Ste 2 (VACANT) | B17: ='Table 1.0'!B16 -> A2 | C17: ='Table 1.0'!C16 -> 12000 | D17: =IF($C17,P16/$C17,0) -> 6.6 | E17: =IF($C17,Q16/$C17,0) -> 6.7485 | F17: =IF($C17,R16/$C17,0) -> 6.6495 | G17: =IF($C17,S16/$C17,0) -> 6.849 | H17: =IF($C17,T16/$C17,0) -> 7.0544167 | I17: =IF($C17,U16/$C17,0) -> 7.2660833 | J17: =IF($C17,V16/$C17,0) -> 7.5415 | K17: =IF($C17,W16/$C17,0) -> 7.9201667 | L17: =IF($C17,X16/$C17,0) -> 8.15775 | N17: Bldg A Suite 3 | O17: Mo 17 | P17: 78494 | Q17: 80849 | R17: 79291 | S17: 80456 | T17: 82870 | U17: 85356 | V17: 87917 | W17: 95172 | X17: 98710 | Y17: 101671
A18: ='Table 1.0'!A17 -> Building A Ste 3 (VACANT) | B18: ='Table 1.0'!B17 -> A3 | C18: ='Table 1.0'!C17 -> 11893 | D18: =IF($C18,P17/$C18,0) -> 6.6000168 | E18: =IF($C18,Q17/$C18,0) -> 6.7980325 | F18: =IF($C18,R17/$C18,0) -> 6.667031 | G18: =IF($C18,S17/$C18,0) -> 6.7649878 | H18: =IF($C18,T17/$C18,0) -> 6.9679643 | I18: =IF($C18,U17/$C18,0) -> 7.1769949 | J18: =IF($C18,V17/$C18,0) -> 7.3923316 | K18: =IF($C18,W17/$C18,0) -> 8.0023543 | L18: =IF($C18,X17/$C18,0) -> 8.2998402
C19: =SUM(C9:C18) -> 129097
C20: Average Potential Lease Rate: | D20: =($C$9*D9+$C$10*D10+$C$11*D11+$C$12*D12+$C$13*D13+$C$14*D14+$C$15*D15+$C$16*D16+$C$17*D17+$C$18*D18)/$C$19 -> 6.1855818 | E20: =($C$9*E9+$C$10*E10+$C$11*E11+$C$12*E12+$C$13*E13+$C$14*E14+$C$15*E15+$C$16*E16+$C$17*E17+$C$18*E18)/$C$19 -> 6.3300822 | F20: =($C$9*F9+$C$10*F10+$C$11*F11+$C$12*F12+$C$13*F13+$C$14*F14+$C$15*F15+$C$16*F16+$C$17*F17+$C$18*F18)/$C$19 -> 6.4213446 | G20: =($C$9*G9+$C$10*G10+$C$11*G11+$C$12*G12+$C$13*G13+$C$14*G14+$C$15*G15+$C$16*G16+$C$17*G17+$C$18*G18)/$C$19 -> 6.5615158 | H20: =($C$9*H9+$C$10*H10+$C$11*H11+$C$12*H12+$C$13*H13+$C$14*H14+$C$15*H15+$C$16*H16+$C$17*H17+$C$18*H18)/$C$19 -> 6.7935661 | I20: =($C$9*I9+$C$10*I10+$C$11*I11+$C$12*I12+$C$13*I13+$C$14*I14+$C$15*I15+$C$16*I16+$C$17*I17+$C$18*I18)/$C$19 -> 6.9973663 | J20: =($C$9*J9+$C$10*J10+$C$11*J11+$C$12*J12+$C$13*J13+$C$14*J14+$C$15*J15+$C$16*J16+$C$17*J17+$C$18*J18)/$C$19 -> 7.2297187 | K20: =($C$9*K9+$C$10*K10+$C$11*K11+$C$12*K12+$C$13*K13+$C$14*K14+$C$15*K15+$C$16*K16+$C$17*K17+$C$18*K18)/$C$19 -> 7.4956351 | L20: =($C$9*L9+$C$10*L10+$C$11*L11+$C$12*L12+$C$13*L13+$C$14*L14+$C$15*L15+$C$16*L16+$C$17*L17+$C$18*L18)/$C$19 -> 7.7258031
D21: =(D20-'Table 1.0'!C23)/'Table 1.0'!C23 -> -0.057721911 | E21: =(E20-D20)/D20 -> 0.023360844 | F21: =(F20-E20)/E20 -> 0.014417254 | G21: =(G20-F20)/F20 -> 0.021828945 | H21: =(H20-G20)/G20 -> 0.035365353 | I21: =(I20-H20)/H20 -> 0.029999008 | J21: =(J20-I20)/I20 -> 0.033205696 | K21: =(K20-J20)/J20 -> 0.036781006 | L21: =(L20-K20)/K20 -> 0.03070694 | N21: 129097 | P21: Yr 1 | Q21: Yr 2 | R21: yr 3
N22: Estimated Expenses | P22: 324853 | Q22: 347544 | R22: 362100 | S22: 372239 | T22: 384197 | U22: 395387 | V22: 406751 | W22: 419841 | X22: 431662
A23: Note- Qantas Airways' actual rental rate is modified gross. Rental rate was converted to NNN for purposes of this table by subtracting estimated exspenses/sq.ft. for the remaining term of lease. | N23: Per Sq.Ft. | P23: =P22/$N$21 -> 2.5163482 | Q23: =Q22/$N$21 -> 2.6921152 | R23: =R22/$N$21 -> 2.8048677 | S23: =S22/$N$21 -> 2.8834055 | T23: =T22/$N$21 -> 2.9760335 | U23: =U22/$N$21 -> 3.0627125 | V23: =V22/$N$21 -> 3.1507394 | W23: =W22/$N$21 -> 3.252136 | ... Y23: =Y22/$N$21 -> 0
A24: Subsequent leasing for space reported as NNN.
A26: (A)- Warehouse Space.

Sheet Table 1.2
A1: TABLE 1.2 -TUCSON AIRPORT CENTER- MONTHS VACANT, FREE RENT, & NEW LEASE PROJECTION (1)
C3: Fiscal Year Ending | D3: ='Table 1.1'!D6 -> 38869 | E3: ='Table 1.1'!E6 -> 39234 | F3: ='Table 1.1'!F6 -> 39600 | G3: ='Table 1.1'!G6 -> 39965 | H3: ='Table 1.1'!H6 -> 40330 | I3: ='Table 1.1'!I6 -> 40695 | J3: ='Table 1.1'!J6 -> 41061 | K3: ='Table 1.1'!K6 -> 41426 | L3: ='Table 1.1'!L6 -> 41791
D4: Yr 1 | E4: Yr 2 | F4: Yr 3 | G4: Yr 4 | H4: Yr 5 | I4: Yr 6 | J4: Yr 7 | K4: Yr 8 | L4: Yr 9 | AA4: Yr 1 | AB4: Yr 2 | AC4: Yr 3 | AD4: Yr 4 | AE4: Yr 5 | AF4: Yr 6 | AG4: Yr 7 | AH4: Yr 8 | AI4: Yr 9
B5: SF | C5: Years In
C6: New Lease | D6: Months Vacant per space in year (months/year) 2
A7: ='Table 1.0'!A8 -> Qantas Airways | B7: ='Table 1.0'!C8 -> 19204 | C7: 5 | G7: =AD7 -> 1.9999856 | L7: =AI7 -> 2.009776 | O7: Qantas Airways | P7: 2801 | Q7: 203370 | R7: 210092 | S7: 214317 | T7: 115416 | U7: 141962 | V7: 146221 | W7: 150607 | X7: 155125 | Y7: 133019 | Z7: 163770 | AA7: =12-((Q7/'Table 1.3'!O9)*12) -> 0 | AB7: =12-((R7/'Table 1.3'!P9)*12) -> 0 | AC7: =12-((S7/'Table 1.3'!Q9)*12) -> 0 | AD7: =12-((T7/'Table 1.3'!R9)*12) -> 1.9999856 | AE7: =12-((U7/'Table 1.3'!S9)*12) -> 0 | AF7: =12-((V7/'Table 1.3'!T9)*12) -> 0 | AG7: =12-((W7/'Table 1.3'!U9)*12) -> 0 | AH7: =12-((X7/'Table 1.3'!V9)*12) -> 0 | AI7: =12-((Y7/'Table 1.3'!W9)*12) -> 2.009776
A8: ='Table 1.0'!A9 -> Davis Select | B8: ='Table 1.0'!C9 -> 12512 | C8: 5 | G8: =AD8 -> 2.0876627 | L8: =AI8 -> 2.0245791 | O8: Davis Select | P8: 2949A | Q8: 69692 | R8: 71193 | S8: 73320 | T8: 71406 | U8: 91816 | V8: 94570 | W8: 97407 | X8: 100329 | Y8: 85905 | Z8: 105916 | AA8: =12-((Q8/'Table 1.3'!O10)*12) -> 0 | AB8: =12-((R8/'Table 1.3'!P10)*12) -> 0 | AC8: =12-((S8/'Table 1.3'!Q10)*12) -> 0 | AD8: =12-((T8/'Table 1.3'!R10)*12) -> 2.0876627 | AE8: =12-((U8/'Table 1.3'!S10)*12) -> 0 | AF8: =12-((V8/'Table 1.3'!T10)*12) -> 0 | AG8: =12-((W8/'Table 1.3'!U10)*12) -> 0 | AH8: =12-((X8/'Table 1.3'!V10)*12) -> 0 | AI8: =12-((Y8/'Table 1.3'!W10)*12) -> 2.0245791
A9: ='Table 1.0'!A10 -> Davis Select (Expansion Space) | B9: ='Table 1.0'!C10 -> 7488 | C9: 5 | G9: =AD9 -> 2.0877936 | L9: =AI9 -> 2.0245452 | O9: Davis Expansion Space | P9: 2949 A | Q9: 41708 | R9: 42607 | S9: 43880 | T9: 42734 | U9: 54949 | V9: 56597 | W9: 58295 | X9: 60044 | Y9: 51411 | Z9: 63387 | AA9: =12-((Q9/'Table 1.3'!O11)*12) -> 0 | AB9: =12-((R9/'Table 1.3'!P11)*12) -> 0 | AC9: =12-((S9/'Table 1.3'!Q11)*12) -> 0 | AD9: =12-((T9/'Table 1.3'!R11)*12) -> 2.0877936 | AE9: =12-((U9/'Table 1.3'!S11)*12) -> 0 | AF9: =12-((V9/'Table 1.3'!T11)*12) -> 0 | AG9: =12-((W9/'Table 1.3'!U11)*12) -> 0 | AH9: =12-((X9/'Table 1.3'!V11)*12) -> 0 | AI9: =12-((Y9/'Table 1.3'!W11)*12) -> 2.0245452
A10: ='Table 1.0'!A11 -> APEX | B10: ='Table 1.0'!C11 -> 15000 | C10: 5 | G10: =AD10 -> 2.0114349 | L10: =AI10 -> 2.0146991 | O10: APEX | P10: 15000 | Q10: 95400 | R10: 99000 | S10: 100800 | T10: 89535 | U10: 110614 | V10: 113932 | W10: 117350 | X10: 120871 | Y10: 103595 | Z10: 127605 | AA10: =12-((Q10/'Table 1.3'!O12)*12) -> 0 | AB10: =12-((R10/'Table 1.3'!P12)*12) -> 0 | AC10: =12-((S10/'Table 1.3'!Q12)*12) -> 0 | AD10: =12-((T10/'Table 1.3'!R12)*12) -> 2.0114349 | AE10: =12-((U10/'Table 1.3'!S12)*12) -> 0 | AF10: =12-((V10/'Table 1.3'!T12)*12) -> 0 | AG10: =12-((W10/'Table 1.3'!U12)*12) -> 0 | AH10: =12-((X10/'Table 1.3'!V12)*12) -> 0 | AI10: =12-((Y10/'Table 1.3'!W12)*12) -> 2.0146991
A11: ='Table 1.0'!A12 -> Iron Mountain Temp. Space | B11: ='Table 1.0'!C12 -> 24000 | C11: 5 | D11: =AA11 -> 9 | J11: =AG11 -> 2.0000145 | O11: Iron Mountain | P11: Bldg E | Q11: 28800 | R11: 118656 | S11: 122216 | T11: 125882 | U11: 129659 | V11: 133548 | W11: 114629 | X11: 140994 | Y11: 145224 | Z11: 149580 | AA11: =12-((Q11/'Table 1.3'!O13)*12) -> 9 | AB11: =12-((R11/'Table 1.3'!P13)*12) -> 0 | AC11: =12-((S11/'Table 1.3'!Q13)*12) -> 0 | AD11: =12-((T11/'Table 1.3'!R13)*12) -> 0 | AE11: =12-((U11/'Table 1.3'!S13)*12) -> 0 | AF11: =12-((V11/'Table 1.3'!T13)*12) -> 0 | AG11: =12-((W11/'Table 1.3'!U13)*12) -> 2.0000145 | AH11: =12-((X11/'Table 1.3'!V13)*12) -> 0 | AI11: =12-((Y11/'Table 1.3'!W13)*12) -> 0
A12: ='Table 1.0'!A13 -> Building C Ste 1 (VACANT) | B12: ='Table 1.0'!C13 -> 7500 | C12: 5 | D12: =AA12 -> 11 | I12: =AF12 -> 1.0274296 | J12: =AG12 -> 0.9999154 | O12: Building C- Suite 1 | P12: Mo 8 | Q12: 4125 | R12: 49624 | S12: 51112 | T12: 52646 | U12: 54225 | V12: 51070 | W12: 54180 | X12: 60731 | Y12: 62553 | Z12: 64430 | AA12: =12-((Q12/'Table 1.3'!O14)*12) -> 11 | AB12: =12-((R12/'Table 1.3'!P14)*12) -> 0 | AC12: =12-((S12/'Table 1.3'!Q14)*12) -> 0 | AD12: =12-((T12/'Table 1.3'!R14)*12) -> 0 | AE12: =12-((U12/'Table 1.3'!S14)*12) -> 0 | AF12: =12-((V12/'Table 1.3'!T14)*12) -> 1.0274296 | AG12: =12-((W12/'Table 1.3'!U14)*12) -> 0.9999154 | AH12: =12-((X12/'Table 1.3'!V14)*12) -> 0 | AI12: =12-((Y12/'Table 1.3'!W14)*12) -> 0
A13: ='Table 1.0'!A14 -> Building C Ste 2 (VACANT) | B13: ='Table 1.0'!C14 -> 7500 | C13: 5 | D13: =AA13 -> 12 | E13: =AB13 -> 5.0864542 | J13: =AG13 -> 2.0490189 | O13: Building C- Suite 2 | P13: Mo 10 | Q13: 0 | R13: 28875 | S13: 50366 | T13: 51877 | U13: 53434 | V13: 55037 | W13: 47841 | X13: 59844 | Y13: 61640 | Z13: 63489 | AA13: =12-((Q13/'Table 1.3'!O15)*12) -> 12 | AB13: =12-((R13/'Table 1.3'!P15)*12) -> 5.0864542 | AC13: =12-((S13/'Table 1.3'!Q15)*12) -> 0 | AD13: =12-((T13/'Table 1.3'!R15)*12) -> 0 | AE13: =12-((U13/'Table 1.3'!S15)*12) -> 0 | AF13: =12-((V13/'Table 1.3'!T15)*12) -> 0 | AG13: =12-((W13/'Table 1.3'!U15)*12) -> 2.0490189 | AH13: =12-((X13/'Table 1.3'!V15)*12) -> 0 | AI13: =12-((Y13/'Table 1.3'!W15)*12) -> 0
A14: ='Table 1.0'!A15 -> Building A Ste 1 (VACANT) | B14: ='Table 1.0'!C15 -> 12000 | C14: 5 | D14: =AA14 -> 6 | I14: =AF14 -> 2.0295298 | O14: Bldg A Suite 1 | P14: Mo 5 | Q14: 32400 | R14: 65772 | S14: 67745 | T14: 69778 | U14: 71871 | V14: 61507 | W14: 75872 | X14: 78148 | Y14: 80493 | Z14: 82908 | AA14: =12-((Q14/'Table 1.3'!O16)*12) -> 6 | AB14: =12-((R14/'Table 1.3'!P16)*12) -> 0 | AC14: =12-((S14/'Table 1.3'!Q16)*12) -> 0 | AD14: =12-((T14/'Table 1.3'!R16)*12) -> 0 | AE14: =12-((U14/'Table 1.3'!S16)*12) -> 0 | AF14: =12-((V14/'Table 1.3'!T16)*12) -> 2.0295298 | AG14: =12-((W14/'Table 1.3'!U16)*12) -> 0 | AH14: =12-((X14/'Table 1.3'!V16)*12) -> 0 | AI14: =12-((Y14/'Table 1.3'!W16)*12) -> 0
A15: ='Table 1.0'!A16 -> Building A Ste 2 (VACANT) | B15: ='Table 1.0'!C16 -> 12000 | C15: 5 | D15: =AA15 -> 12 | E15: =AB15 -> 9.0660147 | J15: =AG15 -> 2.0899256 | O15: Bldg A Suite 2 | P15: Mo 12 | Q15: 0 | R15: 19800 | S15: 79794 | T15: 82188 | U15: 84653 | V15: 87193 | W15: 74736 | X15: 94805 | Y15: 97650 | Z15: 100579 | AA15: =12-((Q15/'Table 1.3'!O17)*12) -> 12 | AB15: =12-((R15/'Table 1.3'!P17)*12) -> 9.0660147 | AC15: =12-((S15/'Table 1.3'!Q17)*12) -> 0 | AD15: =12-((T15/'Table 1.3'!R17)*12) -> 0 | AE15: =12-((U15/'Table 1.3'!S17)*12) -> 0 | AF15: =12-((V15/'Table 1.3'!T17)*12) -> 0 | AG15: =12-((W15/'Table 1.3'!U17)*12) -> 2.0899256 | AH15: =12-((X15/'Table 1.3'!V17)*12) -> 0 | AI15: =12-((Y15/'Table 1.3'!W17)*12) -> 0
A16: ='Table 1.0'!A17 -> Building A Ste 3 (VACANT) | B16: ='Table 1.0'!C17 -> 11893 | C16: 5 | D16: =AA16 -> 12 | E16: =AB16 -> 12 | F16: =AC16 -> 2.1004654 | K16: =AH16 -> 2.0287266 | O16: Bldg A Suite 3 | P16: Mo 17 | Q16: 0 | R16: 0 | S16: 65412 | T16: 80456 | U16: 82870 | V16: 85356 | W16: 87917 | X16: 79083 | Y16: 98468 | Z16: 101422 | AA16: =12-((Q16/'Table 1.3'!O18)*12) -> 12 | AB16: =12-((R16/'Table 1.3'!P18)*12) -> 12 | AC16: =12-((S16/'Table 1.3'!Q18)*12) -> 2.1004654 | AD16: =12-((T16/'Table 1.3'!R18)*12) -> 0 | AE16: =12-((U16/'Table 1.3'!S18)*12) -> 0 | AF16: =12-((V16/'Table 1.3'!T18)*12) -> 0 | AG16: =12-((W16/'Table 1.3'!U18)*12) -> 0 | AH16: =12-((X16/'Table 1.3'!V18)*12) -> 2.0287266 | AI16: =12-((Y16/'Table 1.3'!W18)*12) -> 0
B17: =SUM(B7:B16) -> 129097
A20: First Term Lease Expirations | D20: 24000 | E20: 0 | F20: 19204 | G20: 35000 | H20: 0 | I20: 19500 | J20: 19500 | K20: 11893 | L20: 0
A21: Lease Expirations after First Term | D21: 0 | E21: =E22-E20 -> 0 | F21: 0 | G21: 0 | H21: =H22-H20 -> 0 | I21: 24000 | J21: 0 | K21: 0 | L21: 54204
A22: Total | D22: =D20+D21 -> 24000 | E22: 0 | F22: =F20+F21 -> 19204 | G22: =G20+G21 -> 35000 | H22: 0 | I22: =I20+I21 -> 43500 | J22: =J20+J21 -> 19500 | K22: =K20+K21 -> 11893 | L22: 54204
A23: % of Building | D23: =D22/$B$17 -> 0.18590672 | E23: =E22/$B$17 -> 0 | F23: =F22/$B$17 -> 0.14875636 | G23: =G22/$B$17 -> 0.27111397 | H23: =H22/$B$17 -> 0 | I23: =I22/$B$17 -> 0.33695593 | J23: =J22/$B$17 -> 0.15104921 | K23: =K22/$B$17 -> 0.092124527 | L23: =L22/$B$17 -> 0.41987033
A25: (1) Months vacant calculation for vacant space shows the blended downtime (1 month) between leases.
A26: The 1 month blended downtime between leases is based on a 25% probability that a tenant vacates and it takes 6 months to find a new tenant.

Sheet Table 1.3
A1: TABLE 1.3 -TUCSON AIRPORT CENTER - BASE RENT REVENUES
D3: Fiscal Year Ending | E3: ='Table 1.1'!D6 -> 38869 | F3: ='Table 1.1'!E6 -> 39234 | G3: ='Table 1.1'!F6 -> 39600 | H3: ='Table 1.1'!G6 -> 39965 | I3: ='Table 1.1'!H6 -> 40330 | J3: ='Table 1.1'!I6 -> 40695 | K3: ='Table 1.1'!J6 -> 41061 | L3: ='Table 1.1'!K6 -> 41426 | M3: ='Table 1.1'!L6 -> 41791
E4: Yr 1 | F4: Yr 2 | G4: Yr 3 | H4: Yr 4 | I4: Yr 5 | J4: Yr 6 | K4: Yr 7 | L4: Yr 8 | M4: Yr 9
D6: OCCUPANCY BEFORE VACANCY LOSS: | E6: =E22/(E20) -> #REF! | F6: =F22/(F20) -> #REF! | G6: =G22/(G20) -> #REF! | H6: =H22/(H20) -> #REF! | I6: =I22/(I20) -> #REF! | J6: =J22/(J20) -> #REF! | K6: =K22/(K20) -> #REF! | L6: =L22/(L20) -> #REF! | M6: =M22/(M20) -> #REF!
D7: OCCUPANCY AFTER VACANCY LOSS: | E7: =IF(E6<0.92,E6,0.92) -> #REF! | F7: =IF(F6<0.92,F6,0.92) -> #REF! | G7: =IF(G6<0.9,G6,0.9) -> #REF! | H7: =IF(H6<0.9,H6,0.9) -> #REF! | I7: =IF(I6<0.9,I6,0.9) -> #REF! | J7: =IF(J6<0.9,J6,0.9) -> #REF! | K7: =IF(K6<0.9,K6,0.9) -> #REF! | L7: =IF(L6<0.9,L6,0.9) -> #REF! | M7: =IF(M6<0.9,M6,0.9) -> #REF!
C8: Suite | D8: SF
A9: ='Table 1.0'!A8 -> Qantas Airways | C9: ='Table 1.0'!B8 -> 1 | D9: ='Table 1.0'!C8 -> 19204 | E9: =O9 -> 203370 | F9: =P9 -> 210092 | G9: =Q9 -> 214317 | H9: =R9 -> 138499 | I9: =S9 -> 141962 | J9: =T9 -> 146221 | K9: =U9 -> 150607 | L9: =V9 -> 155125 | M9: =W9 -> 159779 | O9: 203370 | P9: 210092 | Q9: 214317 | R9: 138499 | S9: 141962 | T9: 146221 | U9: 150607 | V9: 155125 | W9: 159779 | X9: 163770
A10: ='Table 1.0'!A9 -> Davis Select | C10: ='Table 1.0'!B9 -> 2 | D10: ='Table 1.0'!C9 -> 12512 | E10: =O10 -> 69692 | F10: =P10 -> 71193 | G10: =Q10 -> 73320 | H10: =R10 -> 86445 | I10: =S10 -> 91816 | J10: =T10 -> 94570 | K10: =U10 -> 97407 | L10: =V10 -> 100329 | M10: =W10 -> 103340 | O10: 69692 | P10: 71193 | Q10: 73320 | R10: 86445 | S10: 91816 | T10: 94570 | U10: 97407 | V10: 100329 | W10: 103340 | X10: 105916
A11: ='Table 1.0'!A10 -> Davis Select (Expansion Space) | C11: ='Table 1.0'!B10 -> 2a | D11: ='Table 1.0'!C10 -> 7488 | E11: =O11 -> 41708 | F11: =P11 -> 42607 | G11: =Q11 -> 43880 | H11: =R11 -> 51735 | I11: =S11 -> 54949 | J11: =T11 -> 56597 | K11: =U11 -> 58295 | L11: =V11 -> 60044 | M11: =W11 -> 61845 | O11: 41708 | P11: 42607 | Q11: 43880 | R11: 51735 | S11: 54949 | T11: 56597 | U11: 58295 | V11: 60044 | W11: 61845 | X11: 63387
A12: ='Table 1.0'!A11 -> APEX | C12: ='Table 1.0'!B11 -> 0 | D12: ='Table 1.0'!C11 -> 15000 | E12: =O12 -> 95400 | F12: =P12 -> 99000 | G12: =Q12 -> 100800 | H12: =R12 -> 107565 | I12: =S12 -> 110614 | J12: =T12 -> 113932 | K12: =U12 -> 117350 | L12: =V12 -> 120871 | M12: =W12 -> 124497 | O12: 95400 | P12: 99000 | Q12: 100800 | R12: 107565 | S12: 110614 | T12: 113932 | U12: 117350 | V12: 120871 | W12: 124497 | X12: 127605
A13: ='Table 1.0'!A12 -> Iron Mountain Temp. Space | C13: ='Table 1.0'!B12 -> 2B | D13: ='Table 1.0'!C12 -> 24000 | E13: =O13 -> 115200 | F13: =P13 -> 118656 | G13: =Q13 -> 122216 | H13: =R13 -> 125882 | I13: =S13 -> 129659 | J13: =T13 -> 133548 | K13: =U13 -> 137555 | L13: =V13 -> 140994 | M13: =W13 -> 145224 | O13: 115200 | P13: 118656 | Q13: 122216 | R13: 125882 | S13: 129659 | T13: 133548 | U13: 137555 | V13: 140994 | W13: 145224 | X13: 149580
A14: ='Table 1.0'!A13 -> Building C Ste 1 (VACANT) | C14: ='Table 1.0'!B13 -> C1 | D14: ='Table 1.0'!C13 -> 7500 | E14: =O14 -> 49500 | F14: =P14 -> 49624 | G14: =Q14 -> 51112 | H14: =R14 -> 52646 | I14: =S14 -> 54225 | J14: =T14 -> 55852 | K14: =U14 -> 59105 | L14: =V14 -> 60731 | M14: =W14 -> 62553 | O14: 49500 | P14: 49624 | Q14: 51112 | R14: 52646 | S14: 54225 | T14: 55852 | U14: 59105 | V14: 60731 | W14: 62553 | X14: 64430
A15: ='Table 1.0'!A14 -> Building C Ste 2 (VACANT) | C15: ='Table 1.0'!B14 -> C2 | D15: ='Table 1.0'!C14 -> 7500 | E15: =O15 -> 49500 | F15: =P15 -> 50119 | G15: =Q15 -> 50366 | H15: =R15 -> 51877 | I15: =S15 -> 53434 | J15: =T15 -> 55037 | K15: =U15 -> 57692 | L15: =V15 -> 59844 | M15: =W15 -> 61640 | O15: 49500 | P15: 50119 | Q15: 50366 | R15: 51877 | S15: 53434 | T15: 55037 | U15: 57692 | V15: 59844 | W15: 61640 | X15: 63489
A16: ='Table 1.0'!A15 -> Building A Ste 1 (VACANT) | C16: ='Table 1.0'!B15 -> A1 | D16: ='Table 1.0'!C15 -> 12000 | E16: =O16 -> 64800 | F16: =P16 -> 65772 | G16: =Q16 -> 67745 | H16: =R16 -> 69778 | I16: =S16 -> 71871 | J16: =T16 -> 74027 | K16: =U16 -> 75872 | L16: =V16 -> 78148 | M16: =W16 -> 80493 | O16: 64800 | P16: 65772 | Q16: 67745 | R16: 69778 | S16: 71871 | T16: 74027 | U16: 75872 | V16: 78148 | W16: 80493 | X16: 82908
A17: ='Table 1.0'!A16 -> Building A Ste 2 (VACANT) | C17: ='Table 1.0'!B16 -> A2 | D17: ='Table 1.0'!C16 -> 12000 | E17: =O17 -> 79200 | F17: =P17 -> 80982 | G17: =Q17 -> 79794 | H17: =R17 -> 82188 | I17: =S17 -> 84653 | J17: =T17 -> 87193 | K17: =U17 -> 90497 | L17: =V17 -> 94805 | M17: =W17 -> 97650 | O17: 79200 | P17: 80982 | Q17: 79794 | R17: 82188 | S17: 84653 | T17: 87193 | U17: 90497 | V17: 94805 | W17: 97650 | X17: 100579
A18: ='Table 1.0'!A17 -> Building A Ste 3 (VACANT) | C18: ='Table 1.0'!B17 -> A3 | D18: ='Table 1.0'!C17 -> 11893 | E18: =O18 -> 78494 | F18: =P18 -> 80849 | G18: =Q18 -> 79291 | H18: =R18 -> 80456 | I18: =S18 -> 82870 | J18: =T18 -> 85356 | K18: =U18 -> 87917 | L18: =V18 -> 95173 | M18: =W18 -> 98468 | O18: 78494 | P18: 80849 | Q18: 79291 | R18: 80456 | S18: 82870 | T18: 85356 | U18: 87917 | V18: 95173 | W18: 98468 | X18: 101422
D19: =SUM(D9:D18) -> 129097
D20: POTENTIAL RENTAL INCOME: | E20: =SUM(E9:E18) -> 846864 | F20: =SUM(F9:F18) -> 868894 | G20: =SUM(G9:G18) -> 882841 | H20: =SUM(H9:H18) -> 847071 | I20: =SUM(I9:I18) -> 876053 | J20: =SUM(J9:J18) -> 902333 | K20: =SUM(K9:K18) -> 932297 | L20: =SUM(L9:L18) -> 966064 | M20: =SUM(M9:M18) -> 995489
D21: ABSORPTION & TURNOVER VACANCY1: | E21: =E22-E20 -> #REF! | F21: =F22-F20 -> #REF! | G21: =G22-G20 -> #REF! | H21: =H22-H20 -> #REF! | I21: =I22-I20 -> #REF! | J21: =J22-J20 -> #REF! | K21: =K22-K20 -> #REF! | L21: =L22-L20 -> #REF! | M21: =M22-M20 -> #REF!
D22: RENTAL INCOME BEFORE VACANCY LOSS: | E22: =#REF! -> #REF! | F22: =#REF! -> #REF! | G22: =#REF! -> #REF! | H22: =#REF! -> #REF! | I22: =#REF! -> #REF! | J22: =#REF! -> #REF! | K22: =#REF! -> #REF! | L22: =#REF! -> #REF! | M22: =#REF! -> #REF!
A25: 1Absorption & Turnover Vacancy: The amount of revenue lost during the initial lease up of vacant space and downtime between leases.

Sheet Table 1.4
A1: TABLE 1.4 - TUCSON AIRPORT CENTER - LEASE COMMISSIONS
C3: Fiscal Year Ending | D3: ='Table 1.3'!E3 -> 38869 | E3: ='Table 1.3'!F3 -> 39234 | F3: ='Table 1.3'!G3 -> 39600 | G3: ='Table 1.3'!H3 -> 39965 | H3: ='Table 1.3'!I3 -> 40330 | I3: ='Table 1.3'!J3 -> 40695 | J3: ='Table 1.3'!K3 -> 41061 | K3: ='Table 1.3'!L3 -> 41426 | L3: ='Table 1.3'!M3 -> 41791
D4: Yr 1 | E4: Yr 2 | F4: Yr 3 | G4: Yr 4 | H4: Yr 5 | I4: Yr 6 | J4: Yr 7 | K4: Yr 8 | L4: Yr 9
B6: Suite | C6: SF
A7: ='Table 1.0'!A8 -> Qantas Airways | B7: ='Table 1.0'!B8 -> 1 | C7: ='Table 1.0'!C8 -> 19204 | G7: 27574 | L7: 31966
A8: ='Table 1.0'!A9 -> Davis Select | B8: ='Table 1.0'!B9 -> 2 | C8: ='Table 1.0'!C9 -> 12512 | G8: 17965 | L8: 20827
A9: ='Table 1.0'!A10 -> Davis Select (Expansion Space) | B9: ='Table 1.0'!B10 -> 2a | C9: ='Table 1.0'!C10 -> 7488 | G9: 10752 | L9: 12464
A10: ='Table 1.0'!A11 -> APEX | B10: ='Table 1.0'!B11 -> 0 | C10: ='Table 1.0'!C11 -> 15000 | G10: 21538 | L10: 24968
A11: ='Table 1.0'!A12 -> Iron Mountain Temp. Space | B11: ='Table 1.0'!B12 -> 2B | C11: ='Table 1.0'!C12 -> 24000 | E11: 37798 | J11: 27386
A12: ='Table 1.0'!A13 -> Building C Ste 1 (VACANT) | B12: ='Table 1.0'!B13 -> C1 | C12: ='Table 1.0'!C13 -> 7500 | D12: 15768 | J12: 11767
A13: ='Table 1.0'!A14 -> Building C Ste 2 (VACANT) | B13: ='Table 1.0'!B14 -> C2 | C13: ='Table 1.0'!C14 -> 7500 | E13: 15768 | J13: 11767
A14: ='Table 1.0'!A15 -> Building A Ste 1 (VACANT) | B14: ='Table 1.0'!B15 -> A1 | C14: ='Table 1.0'!C15 -> 12000 | D14: 20642 | I14: 14956
A15: ='Table 1.0'!A16 -> Building A Ste 2 (VACANT) | B15: ='Table 1.0'!B16 -> A2 | C15: ='Table 1.0'!C16 -> 12000 | E15: 25229 | J15: 18828
A16: ='Table 1.0'!A17 -> Building A Ste 3 (VACANT) | B16: ='Table 1.0'!B17 -> A3 | C16: ='Table 1.0'!C17 -> 11893 | F16: 25004 | K16: 19220
A17: TOTAL | C17: =SUM(C7:C16) -> 129097
A19: New Lease Commission % | D19: 0.06 | E19: =D19 -> 0.06 | F19: =E19 -> 0.06 | G19: =F19 -> 0.06 | H19: =G19 -> 0.06 | I19: =H19 -> 0.06 | J19: =I19 -> 0.06 | K19: =J19 -> 0.06 | L19: =K19 -> 0.06
A20: Renewal Commission % | D20: 0.03 | E20: =D20 -> 0.03 | F20: =E20 -> 0.03 | G20: =F20 -> 0.03 | H20: =G20 -> 0.03 | I20: =H20 -> 0.03 | J20: =I20 -> 0.03 | K20: =J20 -> 0.03 | L20: =K20 -> 0.03
A21: TOTAL LEASE COMMISSIONS | D21: =SUM(D7:D16) -> 36410 | E21: =SUM(E7:E16) -> 78795 | F21: =SUM(F7:F16) -> 25004 | G21: =SUM(G7:G16) -> 77829 | H21: =SUM(H7:H16) -> 0 | I21: =SUM(I7:I16) -> 14956 | J21: =SUM(J7:J16) -> 69748 | K21: =SUM(K7:K16) -> 19220 | L21: =SUM(L7:L16) -> 90225
C23: 7

Sheet Table 1.5
A1: TABLE 1.5 - TUCSON AIRPORT CENTER - TENANT IMPROVEMENTS (A)
C3: Fiscal Year Ending | D3: 38869 | E3: 39234 | F3: 39600 | G3: 39965 | H3: 40330 | I3: 40695 | J3: 41061 | K3: 41426 | L3: 41791
A4: Total Amount | D4: Yr 1 | E4: Yr 2 | F4: Yr 3 | G4: Yr 4 | H4: Yr 5 | I4: Yr 6 | J4: Yr 7 | K4: Yr 8 | L4: Yr 9
B6: Suite | C6: SF
A7: Qantas Airways | B7: 1 | C7: 19204 | D7: =P7 | E7: =Q7 | F7: =R7 | G7: =S7 -> 94431 | H7: =T7 | I7: =U7 | J7: =V7 | K7: =W7 | L7: =X7 -> 109472 | N7: Qantas Airways | O7: 2801 | S7: 94431 | X7: 109472
A8: Davis Select | B8: 2 | C8: 12512 | D8: =P8 | E8: =Q8 | F8: =R8 | G8: =S8 -> 61525 | H8: =T8 | I8: =U8 | J8: =V8 | K8: =W8 | L8: =X8 -> 71324 | N8: Davis Select | O8: 2949A | S8: 61525 | X8: 71324
A9: Davis Select (Expansion Space) | B9: 2a | C9: 7488 | D9: =P9 | E9: =Q9 | F9: =R9 | G9: =S9 -> 36821 | H9: =T9 | I9: =U9 | J9: =V9 | K9: =W9 | L9: =X9 -> 42685 | N9: Davis Expansion Space | O9: 2949 A | S9: 36821 | X9: 42685
A10: APEX | B10: 0 | C10: 15000 | D10: =P10 | E10: =Q10 | F10: =R10 | G10: =S10 -> 73759 | H10: =T10 | I10: =U10 | J10: =V10 | K10: =W10 | L10: =X10 -> 85507 | N10: APEX | O10: 15000 | S10: 73759 | X10: 85507
A11: Iron Mountain Temp. Space (B) | B11: 2B | C11: 24000 | D11: =P11 | E11: =Q11 -> 98880 | F11: =R11 | G11: =S11 | H11: =T11 | I11: =U11 | J11: =V11 -> 28657 | K11: =W11 | L11: =X11 | N11: Iron Mountain | O11: Bldg E | Q11: 98880 | V11: 28657
A12: Building C Ste 1 (VACANT) | B12: C1 | C12: 7500 | D12: =P12 -> 90000 | E12: =Q12 | F12: =R12 | G12: =S12 | H12: =T12 | I12: =U12 | J12: =V12 -> 40299 | K12: =W12 | L12: =X12 | N12: Building C- Suite 1 | O12: Mo 12 | P12: 90000 | V12: 40299
A13: Building C Ste 2 (VACANT) | B13: C2 | C13: 7500 | D13: =P13 | E13: =Q13 -> 92700 | F13: =R13 | G13: =S13 | H13: =T13 | I13: =U13 | J13: =V13 -> 40299 | K13: =W13 | L13: =X13 | N13: Building C- Suite 2 | O13: Mo 18 | Q13: 92700 | V13: 40299
A14: Building A Ste 1 (VACANT) | B14: A1 | C14: 12000 | D14: =P14 -> 144000 | E14: =Q14 | F14: =R14 | G14: =S14 | H14: =T14 | I14: =U14 -> 62601 | J14: =V14 | K14: =W14 | L14: =X14 | N14: Bldg A Suite 1 | O14: Mo 7 | P14: 144000 | U14: 62601
A15: Building A Ste 2 (VACANT) | B15: A2 | C15: 12000 | D15: =P15 | E15: =Q15 -> 148320 | F15: =R15 | G15: =S15 | H15: =T15 | I15: =U15 | J15: =V15 -> 64479 | K15: =W15 | L15: =X15 | N15: Bldg A Suite 2 | O15: Mo 22 | Q15: 148320 | V15: 64479
A16: Building A Ste 3 (VACANT) | B16: A3 | C16: 11893 | D16: =P16 | E16: =Q16 | F16: =R16 -> 151407 | G16: =S16 | H16: =T16 | I16: =U16 | J16: =V16 | K16: =W16 -> 65821 | L16: =X16 | N16: Bldg A Suite 3 | O16: Mo 27 | R16: 151407 | W16: 65821
C17: =SUM(C7:C16) -> 129097 | P17: __________ | Q17: __________ | R17: __________ | S17: __________ | T17: __________ | U17: __________ | V17: __________ | W17: __________ | X17: __________ | Y17: __________
A18: TOTAL TI'S | D18: =SUM(D7:D16) -> 234000 | E18: =SUM(E7:E16) -> 339900 | F18: =SUM(F7:F16) -> 151407 | G18: =SUM(G7:G16) -> 266536 | H18: =SUM(H7:H16) -> 0 | I18: =SUM(I7:I16) -> 62601 | J18: =SUM(J7:J16) -> 173734 | K18: =SUM(K7:K16) -> 65821 | L18: =SUM(L7:L16) -> 308988
C19: New Tenant TI: | D19: 12 | E19: =D19*1.03 -> 12.36 | F19: =E19*1.03 -> 12.7308 | G19: =F19*1.03 -> 13.112724 | H19: =G19*1.03 -> 13.506106 | I19: =H19*1.03 -> 13.911289 | J19: =I19*1.03 -> 14.328628 | K19: =J19*1.03 -> 14.758486 | L19: =K19*1.03 -> 15.201241
C20: Renewal Tenant TI: | D20: 2 | E20: =D20*1.03 -> 2.06 | F20: =E20*1.03 -> 2.1218 | G20: =F20*1.03 -> 2.185454 | H20: =G20*1.03 -> 2.2510176 | I20: =H20*1.03 -> 2.3185481 | J20: =I20*1.03 -> 2.3881046 | K20: =J20*1.03 -> 2.4597477 | L20: =K20*1.03 -> 2.5335402
C21: Fiscal Year Ending | D21: =D3 -> 38869 | E21: =E3 -> 39234 | F21: =F3 -> 39600 | G21: =G3 -> 39965 | H21: =H3 -> 40330 | I21: =I3 -> 40695 | J21: =J3 -> 41061 | K21: =K3 -> 41426 | L21: =L3 -> 41791
A22: $/SF Amount | D22: Yr 1 | E22: Yr 2 | F22: Yr 3 | G22: Yr 4 | H22: Yr 5 | I22: Yr 6 | J22: Yr 7 | K22: Yr 8 | L22: Yr 9
B23: Suite | C23: SF
A24: =A7 -> Qantas Airways | B24: =B7 -> 1 | C24: =C7 -> 19204 | G24: =G7/$C24 -> 4.9172568 | L24: =L7/$C24 -> 5.7004791
A25: =A8 -> Davis Select | B25: =B8 -> 2 | C25: =C8 -> 12512 | G25: =G8/$C25 -> 4.9172794 | L25: =L8/$C25 -> 5.7004476
A26: =A9 -> Davis Select (Expansion Space) | B26: =B9 -> 2a | C26: =C9 -> 7488 | G26: =G9/$C26 -> 4.9173344 | L26: =L9/$C26 -> 5.7004541
A27: =A10 -> APEX | B27: =B10 -> 0 | C27: =C10 -> 15000 | G27: =G10/$C27 -> 4.9172667 | L27: =L10/$C27 -> 5.7004667
A28: =A11 -> Iron Mountain Temp. Space (B) | B28: =B11 -> 2B | C28: =C11 -> 24000 | E28: =E11/$C28 -> 4.12 | J28: =J11/$C28 -> 1.1940417
A29: =A12 -> Building C Ste 1 (VACANT) | B29: =B12 -> C1 | C29: =C12 -> 7500 | D29: =D12/$C29 -> 12 | J29: =J12/$C29 -> 5.3732
A30: =A13 -> Building C Ste 2 (VACANT) | B30: =B13 -> C2 | C30: =C13 -> 7500 | E30: =E13/$C30 -> 12.36 | J30: =J13/$C30 -> 5.3732
A31: =A14 -> Building A Ste 1 (VACANT) | B31: =B14 -> A1 | C31: =C14 -> 12000 | D31: =D14/$C31 -> 12 | I31: =I14/$C31 -> 5.21675
A32: =A15 -> Building A Ste 2 (VACANT) | B32: =B15 -> A2 | C32: =C15 -> 12000 | E32: =E15/$C32 -> 12.36 | J32: =J15/$C32 -> 5.37325
A33: =A16 -> Building A Ste 3 (VACANT) | B33: =B16 -> A3 | C33: =C16 -> 11893 | F33: =F16/$C33 -> 12.730766 | K33: =K16/$C33 -> 5.534432
C34: =SUM(C24:C33) -> 129097
A35: Total SF Expiring/ New Leases | D35: =C12+C14 -> 19500 | E35: =C11+C13+C15 -> 43500 | F35: =C16 -> 11893 | G35: =C7+C8+C9+C10 -> 54204 | H35: =0 -> 0 | I35: =C14 -> 12000 | J35: =C15+C13+C12+C11 -> 51000 | K35: =C16 -> 11893 | L35: =C7+C8+C9+C10 -> 54204
A36: TOTAL TI'S ($/SF Expiring-New Leases) | D36: =IF(D35=0,0,D18/D35) -> 12 | E36: =IF(E35=0,0,E18/E35) -> 7.8137931 | F36: =IF(F35=0,0,F18/F35) -> 12.730766 | G36: =IF(G35=0,0,G18/G35) -> 4.9172755 | H36: =IF(H35=0,0,H18/H35) -> 0 | I36: =IF(I35=0,0,I18/I35) -> 5.21675 | J36: =IF(J35=0,0,J18/J35) -> 3.406549 | K36: =IF(K35=0,0,K18/K35) -> 5.534432 | L36: =IF(L35=0,0,L18/L35) -> 5.7004649
A37: (A)- Tenant Improvement amounts calculated based on a 75% probability that tenants will renew.
A38: (B)- Assumes New Tenant Improvement allowance of $4.00/sq.ft. and Renewal Tenant Allowance of $2.00/sq.ft. as the space is 100% warehouse.

Sheet Table 2
A1: =+'Table 1A'!D1 -> TUCSON AIRPORT CENTER
A2: TABLE 2.0 : HISTORICAL EXPENSE & 1ST YEAR PROJECTION
A4: Net Rentable: | B4: 129097
A5: Leased Square Footage: | B5: 54204
A6: % Occupied as of March 1, 2005: | B6: =B5/B4 -> 0.41987033
B7: 2002 | C7: $/SF | D7: 2003 | E7: $/SF | F7: 2004 | G7: $/SF | H7: Year 1 | I7: $/SF
B8: Actual | D8: Actual | F8: Actual | H8: Estimated
A9: 12-Month Average Occupancy
A10: Base Rent | B10: 488318.57 | C10: =B10/$B$4 -> 3.782571 | D10: 466546.99 | E10: =D10/$B$4 -> 3.6139259 | F10: 381265 | G10: =F10/$B$4 -> 2.9533219 | H10: 538926 | I10: =H10/$B$4 -> 4.1745819
A11: Cam Reimbursement | B11: 52865.28 | C11: =B11/$B$4 -> 0.40950045 | D11: 44348.69 | E11: =D11/$B$4 -> 0.34352998 | F11: 29564 | G11: =F11/$B$4 -> 0.2290061 | H11: 75478 | I11: =H11/$B$4 -> 0.58466115
A12: Insurance Reimbursement | B12: 2591.04 | C12: =B12/$B$4 -> 0.02007049 | D12: 2080.7 | E12: =D12/$B$4 -> 0.016117338 | F12: 822 | G12: =F12/$B$4 -> 0.0063673052 | H12: 11472 | I12: =H12/$B$4 -> 0.088863413
A13: RE Taxes Reimbursed | B13: 63202.08 | C13: =B13/$B$4 -> 0.48957048 | D13: 51029.98 | E13: =D13/$B$4 -> 0.39528401 | F13: 30199 | G13: =F13/$B$4 -> 0.23392488 | H13: 64245 | I13: =H13/$B$4 -> 0.49764905
A14: Maintenance Tenant | B14: 5347.36 | C14: =B14/$B$4 -> 0.041421257 | D14: 4623.11 | E14: =D14/$B$4 -> 0.035811134 | F14: 4500 | G14: =F14/$B$4 -> 0.03485751 | H14: 0 | I14: =H14/$B$4 -> 0
A15: Other Income Tenant | B15: 8224.62 | C15: =B15/$B$4 -> 0.063708839 | D15: 0 | E15: =D15/$B$4 -> 0 | F15: 74175 | G15: =F15/$B$4 -> 0.57456796 | H15: 0 | I15: =H15/$B$4 -> 0
A16: Interest Income Other | B16: 15.49 | C16: =B16/$B$4 -> 0.0001199873 | D16: 0 | E16: =D16/$B$4 -> 0 | F16: 11375.68 | G16: =F16/$B$4 -> 0.088117307 | H16: 0 | I16: =H16/$B$4 -> 0
A17: Dividends | B17: 50 | C17: =B17/$B$4 -> 0.00038730567 | D17: 63.33 | E17: =D17/$B$4 -> 0.00049056136 | F17: 32.01 | G17: =F17/$B$4 -> 0.00024795309 | H17: 0 | I17: =H17/$B$4 -> 0
A18: GROSS INCOME | B18: =SUM(B10:B17) -> 620614.44 | C18: =B18/$B$4 -> 4.8073498 | D18: =SUM(D10:D17) -> 568692.8 | E18: =D18/$B$4 -> 4.4051589 | F18: =SUM(F10:F17) -> 531932.69 | G18: =F18/$B$4 -> 4.1204109 | H18: =SUM(H10:H17) -> 690121 | I18: =H18/$B$4 -> 5.3457555
A20: Operating Expenses
A21: Property Management | B21: 35679.7 | C21: =B21/$B$4 -> 0.276379 | D21: 39392.69 | E21: =D21/$B$4 -> 0.30514024 | F21: 31876.43 | G21: =F21/$B$4 -> 0.24691844 | H21: 23853 | I21: =H21/$B$4 -> 0.18476804
A22: RE Taxes | B22: 136597.95 | C22: =B22/$B$4 -> 1.0581032 | D22: =66884.09 -> 66884.09 | E22: =D22/$B$4 -> 0.51809174 | F22: 191101.73 | G22: =F22/$B$4 -> 1.4802957 | H22: 140000 | I22: =H22/$B$4 -> 1.0844559
A23: Insurance | B23: 14827.5 | C23: =B23/$B$4 -> 0.1148555 | D23: 5404.99 | E23: =D23/$B$4 -> 0.041867665 | F23: 12541.7 | G23: =F23/$B$4 -> 0.09714943 | H23: 25000 | I23: =H23/$B$4 -> 0.19365283
A24: Utilities | B24: 37981.75 | C24: =B24/$B$4 -> 0.29421094 | D24: 34202.97 | E24: =D24/$B$4 -> 0.26494008 | F24: 27327.58 | G24: =F24/$B$4 -> 0.21168253 | H24: 40000 | I24: =H24/$B$4 -> 0.30984454
A25: HVAC | B25: 120 | C25: =B25/$B$4 -> 0.00092953361 | D25: 5888.33 | E25: =D25/$B$4 -> 0.045611672 | F25: 2487.33 | G25: =F25/$B$4 -> 0.01926714 | H25: 25000 | I25: =H25/$B$4 -> 0.19365283
A26: Repairs & Maint. | B26: 740.55 | C26: =B26/$B$4 -> 0.0057363843 | D26: 40523.98 | E26: =D26/$B$4 -> 0.31390334 | F26: 3709.32 | G26: =F26/$B$4 -> 0.028732813 | H26: 46000 | I26: =H26/$B$4 -> 0.35632122
A27: Landscaping | B27: 19663 | C27: =B27/$B$4 -> 0.15231183 | D27: 11825.5 | E27: =D27/$B$4 -> 0.091601664 | F27: 12669 | G27: =F27/$B$4 -> 0.098135511 | H27: 15000 | I27: =H27/$B$4 -> 0.1161917
A28: Misc. Bldg | B28: 256.42 | C28: =B28/$B$4 -> 0.0019862584 | D28: 313.99 | E28: =D28/$B$4 -> 0.0024322021 | F28: 3382.84 | G28: =F28/$B$4 -> 0.026203862 | H28: 10000 | I28: =H28/$B$4 -> 0.077461134
A29: Misc. Other | B29: 439.13 | C29: =B29/$B$4 -> 0.0034015508 | D29: 343.52 | E29: =D29/$B$4 -> 0.0026609449 | F29: 400 | G29: =F29/$B$4 -> 0.0030984454 | H29: 0 | I29: =H29/$B$4 -> 0
A30: Office Exp | B30: 1370.9 | C30: =B30/$B$4 -> 0.010619147 | D30: 1228.93 | E30: =D30/$B$4 -> 0.0095194311 | F30: 3173 | G30: =F30/$B$4 -> 0.024578418 | H30: 0 | I30: =H30/$B$4 -> 0
A31: Total Operating Expenses | B31: =SUM(B21:B30) -> 247676.9 | C31: =B31/$B$4 -> 1.9185334 | D31: =SUM(D21:D30) -> 206008.99 | E31: =D31/$B$4 -> 1.595769 | F31: =SUM(F21:F30) -> 288668.93 | G31: =F31/$B$4 -> 2.2360623 | H31: =SUM(H21:H30) -> 324853 | I31: =H31/$B$4 -> 2.5163482
A32: Non-Reimbursable Expenses | H32: (A)
A33: Leasing | B33: 20098.75 | C33: =B33/$B$4 -> 0.1556872 | D33: 28378.03 | E33: =D33/$B$4 -> 0.21981944 | F33: 18816.2 | G33: =F33/$B$4 -> 0.14575242 | H33: 0 | I33: =H33/$B$4 -> 0
A34: Accounting | B34: 5821 | C34: =B34/$B$4 -> 0.045090126 | D34: 5513 | E34: =D34/$B$4 -> 0.042704323 | F34: 5306 | G34: =F34/$B$4 -> 0.041100878 | H34: 0 | I34: =H34/$B$4 -> 0
A35: Legal | B35: 504 | C35: =B35/$B$4 -> 0.0039040411 | D35: 1890.6 | E35: =D35/$B$4 -> 0.014644802 | F35: 4103.8 | G35: =F35/$B$4 -> 0.0317885 | H35: 0 | I35: =H35/$B$4 -> 0
A36: Professional Services | B36: 4381.34 | C36: =B36/$B$4 -> 0.033938356 | D36: 0 | E36: =D36/$B$4 -> 0 | F36: 19265.25 | G36: =F36/$B$4 -> 0.14923081 | H36: 0 | I36: =H36/$B$4 -> 0
A37: Total Non-Reimbursable Expenses | B37: =SUM(B33:B36) -> 30805.09 | C37: =B37/$B$4 -> 0.23861972 | D37: =SUM(D33:D36) -> 35781.63 | E37: =D37/$B$4 -> 0.27716856 | F37: =SUM(F33:F36) -> 47491.25 | G37: =F37/$B$4 -> 0.36787261 | H37: =SUM(H33:H36) -> 0 | I37: =H37/$B$4 -> 0
A38: NET OPERATING INCOME | B38: =B18-B31-B37 -> 342132.45 | C38: =B38/$B$4 -> 2.6501968 | D38: =D18-D31-D37 -> 326902.18 | E38: =D38/$B$4 -> 2.5322214 | F38: =F18-F31-F37 -> 195772.51 | G38: =F38/$B$4 -> 1.5164761 | H38: =H18-H31-H37 -> 365268 | I38: =H38/$B$4 -> 2.8294073
A40: (A)- We account for these expenses below the NOI line.

Sheet Table 3.0
C3: CAPITALIZATION | J3: PROJECT STATISTICS | O3: UNIT COSTS
C4: Property Purchases | J4: Land (sf) | K4: Land (Ac.) | L4: Amenity Center | M4: Square Footage | Q4: Total | R4: $ Unit | S4: $ per SF
E5: 1950 Hoffman | G5: ='Purchase Price'!O5 -> 1334287.3 | J5: 589933 | K5: =J5/43560 -> 13.542998 | L5: (y/n) | M5: =Clubhouse!C4 -> 2120 | O5: Land & Sunk Costs | Q5: =G5 -> 1334287.3 | R5: =Q5/K$7 -> 18531.768 | S5: =Q5/K$8 -> 20.590853
E6: Plus: | G6: 0 | L6: y | O6: Hard Costs - Buildings | Q6: 0 | R6: =Q6/K$7 -> 0 | S6: =Q6/K$8 -> 0
D7: Less: Acquisition Loan | G7: =-K22 -> -1175000 | H7: =-G7/SUM(G5:G6) -> 0.88061995 | J7: # Pads | K7: ='Rent Roll'!C3 -> 72 | O7: Hard Costs - Sitework | Q7: =Infrastructure!D34 -> 1368706 | R7: =Q7/K$7 -> 19009.806 | S7: =Q7/K$8 -> 21.122006
D8: Less: Seller Carryback | G8: =-K23 -> 0 | J8: Total sf: | K8: =K7*900 -> 64800 | L8: Golf Cart Usage | M8: Glamping Occup. | O8: Hard Costs - Amenities | Q8: ='Cost Curves'!F22 -> 631000 | R8: =Q8/K$7 -> 8763.8889 | S8: =Q8/K$8 -> 9.7376543
D9: Plus: Org. & Closing Costs | G9: ='Org. & Closing Costs'!G28 -> 17000 | J9: # Laundry Vending | K9: 2 | L9: 0.7 | M9: 0.5 | O9: Soft Costs | Q9: ='Cost Curves'!F35 -> 498000 | R9: =Q9/K$7 -> 6916.6667 | S9: =Q9/K$8 -> 7.6851852
D10: Plus: Loan Fees | G10: =(K22*Q22+R22)+(K24*Q24+R24) -> 37745 | J10: # Soda Vending | K10: 2 | O10: Contractor Fee | Q10: =S127 -> 120000 | R10: =Q10/K$7 -> 1666.6667 | S10: =Q10/K$8 -> 1.8518519
D11: Plus: Start-Up Mgmt. Fee (% of Purchase Price) | G11: 0 | O11: Contingency | P11: =G133 -> 0.075 | Q11: =S133 -> 204000 | R11: =Q11/K$7 -> 2833.3333 | S11: =Q11/K$8 -> 3.1481481
D12: Plus: Working Capital | G12: 1241134 | J12: CAPITAL CONSTRAINTS | O12: Sub-Total | Q12: =SUM(Q5:Q11) -> 4155993.3 | R12: =Q12/K$7 -> 57722.129 | S12: =Q12/K$8 -> 64.135699
D13: Plus: | J13: Cash Raised | K13: Cash Used | L13: Debt. Avail. | M13: Peak Debt
C14: Initial Equity Investment | G14: =SUM(G5:G13) -> 1455166.3 | J14: ='Members Capital'!I14 -> 1127750.1 | K14: =Worksheet!D23 -> 1127750.1 | L14: =K22+K24 -> 3675000 | M14: =Worksheet!D34 -> 3358369.6 | O14: FF&E | Q14: ='FF&E'!L49 -> 222000 | R14: =Q14/K7 -> 3083.3333 | S14: =Q14/$K$8 -> 3.4259259
D16: Less: Acq. Fee Reinvested | G16: =-G11 -> 0 | J16: ='Members Capital'!G8 -> 281774.22 | K16: + LOC Converted | O16: Financing Expenses | Q16: =SUM(S111:S113)+G10 -> 1282364.9 | R16: =Q16/$K$7 -> 17810.623 | S16: =Q16/$K$8 -> 19.789582
D17: Less: Initial Equity + Ph II Capital | G17: =-'Members Capital'!G7-'Members Capital'!G8-'Members Capital'!G16-'Members Capital'!G17-'Members Capital'!G18 -> -1428416.2 | J17: ='Members Capital'!G7 -> 45642 | K17: + Acq. Fee Converted | O17: Total | Q17: =SUM(Q12:Q16) -> 5660358.2 | R17: =Q17/$K$7 -> 78616.086 | S17: =Q17/$K$8 -> 87.351206
C18: Add'l. Acquisition Equity Required | G18: =SUM(G14:G17) -> 26750.06 | J18: =SUM(J14:J17) -> 1455166.3 | K18: Total Capital
D20: Add: New Capital ("Mezz") | G20: 0 | J20: PROJECT FINANCING
C21: Total Cash Raised from Investors | G21: =G18+G20 -> 26750.06 | K21: Loan Amount | L21: LTC (1) | M21: Int. Rate | N21: Loan Type | O21: Term - Yrs. | P21: Amort. - Mo's. | Q21: Pts. & Fees | R21: Legal Fees | S21: Mo. Initiated
C22: Total Equity & Mezz. | G22: =G14+G20 -> 1455166.3 | J22: Acq. & Const. | K22: 1175000 | L22: =K22/SUM(G5:G6) -> 0.88061995 | M22: 0.095 | N22: Int. Only | O22: 1 | P22: N/A | Q22: 0.01 | R22: 995
J23: Seller Carryback | K23: 0 | M23: 0 | N23: Int. Only | O23: 1 | P23: N/A | Q23: 0 | R23: See Org. Costs
C24: TOTAL CAPITAL COMMITMENTS | J24: Const. Loan | K24: 2500000 | M24: =M22 -> 0.095 | N24: Int. Only | O24: 1 | P24: N/A | Q24: =Q22 -> 0.01 | R24: 0 | S24: 36
G25: Investment | H25: Prorata Share | J25: Total | K25: =SUM(K22:K24) -> 3675000 | L25: =MAX(Balances!I37:AR37) -> 0.56761111
E26: Dabdoub Acquisitions | G26: ='Members Capital'!G17 -> 1000000 | H26: =G26/G31 -> 0.65443228
E27: Nexus Management | G27: ='Members Capital'!G8+'Members Capital'!G18 -> 357774.22 | H27: =G27/G31 -> 0.234139 | K27: Peak Loan Amt. | L27: DCR | M27: Interest Rate | N27: Loan Type | O27: Term (Years) | P27: Amort. Mo's | Q27: Pts. & Fees | R27: Legal Fees | S27: Notes
E28: Mark | G28: ='Members Capital'!H22 -> 99625.77 | H28: =G28/G31 -> 0.06519832 | J28: Perm. Loan | K28: ='Perm Loan'!BX12 -> 2230000 | L28: 1.25 | M28: 0.06 | N28: Amort. | O28: 30 | P28: 360 | Q28: 0.011 | R28: 5000 | S28: (2)
E29: Manager | G29: ='Members Capital'!G7 -> 45642 | H29: =G29/G31 -> 0.029869598 | J29: (1) LTC excludes financing costs
E30: Cort | G30: ='Members Capital'!G16 -> 25000 | H30: =G30/G31 -> 0.016360807 | J30: (2) Phased loan with issuance at end of years 2-8
G31: =SUM(G26:G30) -> 1528042 | H31: =SUM(H26:H30) -> 1
J33: Year 1 | K33: Year 2 | L33: Year 3 | M33: Year 4 | N33: Year 5 | O33: Year 6 | P33: Year 7 | Q33: Year 8 | R33: Year 9 | S33: Cumulative
C35: RV RENTAL INCOME
D36: Short-Term RV Rental Income | J36: =SUM(Monthly!K8:V8) -> 0 | K36: =SUM(Monthly!W8:AH8) -> 151200 | L36: =SUM(Monthly!AI8:AT8) -> 163800 | M36: =SUM(Monthly!AU8:BF8) -> 176400 | N36: =SUM(Monthly!BG8:BR8) -> 189000 | O36: =SUM(Monthly!BS8:CD8) -> 201600 | P36: =SUM(Monthly!CE8:CP8) -> 214200 | Q36: =SUM(Monthly!CQ8:DB8) -> 226800 | R36: =SUM(Monthly!DC8:DN8) -> 239400 | S36: =SUM(J36:R36) -> 1562400
D37: Long-Term RV Rental Income | J37: =SUM(Monthly!K9:V9) -> 0 | K37: =SUM(Monthly!W9:AH9) -> 322422 | L37: =SUM(Monthly!AI9:AT9) -> 331905 | M37: =SUM(Monthly!AU9:BF9) -> 341388 | N37: =SUM(Monthly!BG9:BR9) -> 350871 | O37: =SUM(Monthly!BS9:CD9) -> 360354 | P37: =SUM(Monthly!CE9:CP9) -> 369837 | Q37: =SUM(Monthly!CQ9:DB9) -> 379320 | R37: =SUM(Monthly!DC9:DN9) -> 388803 | S37: =SUM(J37:R37) -> 2844900
C38: SUB-TOTAL | J38: =SUM(J36:J37) -> 0 | K38: =SUM(K36:K37) -> 473622 | L38: =SUM(L36:L37) -> 495705 | M38: =SUM(M36:M37) -> 517788 | N38: =SUM(N36:N37) -> 539871 | O38: =SUM(O36:O37) -> 561954 | P38: =SUM(P36:P37) -> 584037 | Q38: =SUM(Q36:Q37) -> 606120 | R38: =SUM(R36:R37) -> 628203 | S38: =SUM(J38:R38) -> 4407300
C40: Golf Cart Rentals ($/day) (# carts) | G40: 75 | H40: 4 | J40: =SUM(Monthly!K12:V12) -> 0 | K40: =SUM(Monthly!W12:AH12) -> 76650 | L40: =SUM(Monthly!AI12:AT12) -> 76650 | M40: =SUM(Monthly!AU12:BF12) -> 76860 | N40: =SUM(Monthly!BG12:BR12) -> 76650 | O40: =SUM(Monthly!BS12:CD12) -> 76650 | P40: =SUM(Monthly!CE12:CP12) -> 76650 | Q40: =SUM(Monthly!CQ12:DB12) -> 76650 | R40: =SUM(Monthly!DC12:DN12) -> 76650 | S40: =SUM(I40:R40) -> 613410
C41: Glamping Rentals ($/night) (# spaces) | G41: 40 | H41: 10 | J41: =SUM(Monthly!K13:V13) -> 0 | K41: =SUM(Monthly!W13:AH13) -> 73000 | L41: =SUM(Monthly!AI13:AT13) -> 73000 | M41: =SUM(Monthly!AU13:BF13) -> 73200 | N41: =SUM(Monthly!BG13:BR13) -> 73000 | O41: =SUM(Monthly!BS13:CD13) -> 73000 | P41: =SUM(Monthly!CE13:CP13) -> 73000 | Q41: =SUM(Monthly!CQ13:DB13) -> 73000 | R41: =SUM(Monthly!DC13:DN13) -> 73000 | S41: =SUM(I41:R41) -> 584200
C42: SUB-TOTAL | J42: =J40+J41 -> 0 | K42: =K40+K41 -> 149650 | L42: =L40+L41 -> 149650 | M42: =M40+M41 -> 150060 | N42: =N40+N41 -> 149650 | O42: =O40+O41 -> 149650 | P42: =P40+P41 -> 149650 | Q42: =Q40+Q41 -> 149650 | R42: =R40+R41 -> 149650 | S42: =SUM(J42:R42) -> 1197610
C44: TOTAL RENTAL INCOME | J44: =J38+J42 -> 0 | K44: =K38+K42 -> 623272 | L44: =L38+L42 -> 645355 | M44: =M38+M42 -> 667848 | N44: =N38+N42 -> 689521 | O44: =O38+O42 -> 711604 | P44: =P38+P42 -> 733687 | Q44: =Q38+Q42 -> 755770 | R44: =R38+R42 -> 777853 | S44: =SUM(J44:R44) -> 5604910
C46: OTHER INCOME
D47: Laundry ($/unit/month) | G47: 20 | J47: =SUM(Monthly!K19:V19) -> 0 | K47: =SUM(Monthly!W19:AH19) -> 9396 | L47: =SUM(Monthly!AI19:AT19) -> 9396 | M47: =SUM(Monthly!AU19:BF19) -> 9396 | N47: =SUM(Monthly!BG19:BR19) -> 9396 | O47: =SUM(Monthly!BS19:CD19) -> 9396 | P47: =SUM(Monthly!CE19:CP19) -> 9396 | Q47: =SUM(Monthly!CQ19:DB19) -> 9396 | R47: =SUM(Monthly!DC19:DN19) -> 9396 | S47: =SUM(J47:R47) -> 75168
D48: Convenience Store Sales (gross revenue per day) | G48: 150 | J48: =SUM(Monthly!K20:V20) -> 0 | K48: =SUM(Monthly!W20:AH20) -> 54750 | L48: =SUM(Monthly!AI20:AT20) -> 54750 | M48: =SUM(Monthly!AU20:BF20) -> 54900 | N48: =SUM(Monthly!BG20:BR20) -> 54750 | O48: =SUM(Monthly!BS20:CD20) -> 54750 | P48: =SUM(Monthly!CE20:CP20) -> 54750 | Q48: =SUM(Monthly!CQ20:DB20) -> 54750 | R48: =SUM(Monthly!DC20:DN20) -> 54750 | S48: =SUM(J48:R48) -> 438150
D49: Laundry Vending ($/unit/month) | G49: 10 | J49: =SUM(Monthly!K21:V21) -> 0 | K49: =SUM(Monthly!W21:AH21) -> 4698 | L49: =SUM(Monthly!AI21:AT21) -> 4698 | M49: =SUM(Monthly!AU21:BF21) -> 4698 | N49: =SUM(Monthly!BG21:BR21) -> 4698 | O49: =SUM(Monthly!BS21:CD21) -> 4698 | P49: =SUM(Monthly!CE21:CP21) -> 4698 | Q49: =SUM(Monthly!CQ21:DB21) -> 4698 | R49: =SUM(Monthly!DC21:DN21) -> 4698 | S49: =SUM(J49:R49) -> 37584
...

Sheet CF0
B3: Current Basis: | E3: 1888209.9
B5: Ph II Capital Raised | E5: ='Members Capital'!H15 -> 1101000
B6: Accumulated Pref
B7: Sub-Total | E7: =E5+E6 -> 1101000
B9: New Equity Required

Sheet Distributions
D2: Year 1 | P2: Year 2 | AB2: Year 3 | AN2: Year 4 | AZ2: Year 5 | BL2: Year 6 | BX2: Year 7 | CJ2: Year 8 | CV2: Year 9
D3: =Monthly!K4 -> 45413 | E3: =Monthly!L4 -> 45444 | F3: =Monthly!M4 -> 45474 | G3: =Monthly!N4 -> 45505 | H3: =Monthly!O4 -> 45536 | I3: =Monthly!P4 -> 45566 | J3: =Monthly!Q4 -> 45597 | K3: =Monthly!R4 -> 45627 | ... DG3: =Monthly!DN4 -> 48670
D4: May | E4: June | F4: July | G4: August | H4: September | I4: October | J4: November | K4: December | L4: January | M4: February | N4: March | O4: April | P4: May | Q4: June | R4: July | S4: August | T4: September | U4: October | V4: November | W4: December | X4: January | Y4: February | Z4: March | AA4: April | AB4: May | AC4: June | AD4: July | AE4: August | AF4: September | AG4: October | AH4: November | AI4: December | AJ4: January | AK4: February | AL4: March | AM4: April | AN4: May | AO4: June | AP4: July | AQ4: August | AR4: September | AS4: October | AT4: November | AU4: December | AV4: January | AW4: February | AX4: March | AY4: April | AZ4: May | BA4: June | BB4: July | BC4: August | BD4: September | BE4: October | BF4: November | BG4: December | BH4: January | BI4: February | BJ4: March | BK4: April | BL4: May | BM4: June | BN4: July | BO4: August | BP4: September | BQ4: October | BR4: November | BS4: December | BT4: January | BU4: February | BV4: March | BW4: April | BX4: May | BY4: June | BZ4: July | CA4: August | CB4: September | CC4: October | CD4: November | CE4: December | CF4: January | CG4: February | CH4: March | CI4: April | CJ4: May | CK4: June | CL4: July | CM4: August | CN4: September | CO4: October | CP4: November | CQ4: December | CR4: January | CS4: February | CT4: March | CU4: April | CV4: May | CW4: June | CX4: July | CY4: August | CZ4: September | DA4: October | DB4: November | DC4: December | DD4: January | DE4: February | DF4: March | DG4: April | DI4: Total
