Workbook

Sheet Executive Summary
A1: HOTEL BRENDLE - CASH-OUT REFINANCE REQUEST
A2: Prepared: May 04, 2026
A4: PROPERTY INFORMATION
A5: Address: | B5: 601 E Ave A, Robstown, TX 78380
A6: Property Type: | B6: Historic Hotel - Extended Stay
A7: Total Rooms: | B7: 67
A8: Currently Available: | B8: 24
A9: Currently Occupied: | B9: 18
A10: To Be Renovated: | B10: 43
A11: Renovation Timeline: | B11: 6 months
A13: LOAN REQUEST
A14: Amount Requested: | B14: 850000
A16: USE OF PROCEEDS
A17: Existing Debt Payoff | B17: 150000
A18: Renovation & Amenities (43 rooms) | B18: ='Sources & Uses'!B9
A19: Contingency | B19: ='Sources & Uses'!B10
A20: Total Uses | B20: ='Sources & Uses'!B11
A22: LOAN TERMS
A23: Interest Rate: | B23: 0.075
A24: Amortization: | B24: 25 years
A25: Monthly Payment (P&I): | B25: 6281.43
A26: Annual Debt Service: | B26: =B$B25*12
A28: CURRENT OPERATIONS (April 2026)
A29: Occupied Rooms: | B29: 18
A30: Monthly Revenue: | B30: 15340
A31: Annual NOI: | B31: ='Current Operations'!B25
A33: STABILIZED PROJECTIONS (Year 3)
A34: Stabilized Occupancy: | B34: 0.8
A35: Stabilized Occupied Rooms: | B35: =67*B$34
A36: Annual Gross Revenue: | B36: ='Annual Summary'!B6
A37: Annual Operating Expenses: | B37: ='Annual Summary'!C6
A38: Stabilized NOI: | B38: ='Annual Summary'!D6
A39: DSCR: | B39: ='Annual Summary'!G6
A41: PROPERTY VALUATION
A42: Stabilized Value (Year 3, 10% cap): | B42: ='Property Valuation'!B11
A43: Loan Amount: | B43: 850000
A44: Loan-to-Value (LTV): | B44: ='Property Valuation'!B16
A45: Owner Equity: | B45: ='Property Valuation'!B17
A47: REVENUE SOURCES
A48: Room Rental Income
...

Sheet Renovation Budget Detail
A1: RENOVATION BUDGET - LINE ITEM DETAIL
A3: LIGHT RENOVATION (7 rooms @ $1,217/room)
A4: Item | B4: Quantity | C4: Unit | D4: Unit Cost | E4: Extended | F4: Total
A5: Paint - Primer | B5: 2 | C5: gallon | D5: 35 | E5: =B5*D5
A6: Paint - Finish | B6: 4 | C6: gallon | D6: 45 | E6: =B6*D6
A7: Floor Sander Rental | B7: 0.33 | C7: day | D7: 90 | E7: =B7*D7
A8: Floor Stain | B8: 1.5 | C8: gallon | D8: 50 | E8: =B8*D8
A9: Polyurethane | B9: 1 | C9: gallon | D9: 60 | E9: =B9*D9
A10: Sandpaper/Supplies | B10: 1 | C10: lot | D10: 30 | E10: =B10*D10
A11: Drywall Sheet | B11: 1 | C11: sheet | D11: 13 | E11: =B11*D11
A12: Joint Compound | B12: 1 | C12: bucket | D12: 18 | E12: =B12*D12
A13: Drywall Tape/Supplies | B13: 1 | C13: lot | D13: 15 | E13: =B13*D13
A14: Light Fixtures | B14: 2 | C14: each | D14: 40 | E14: =B14*D14
A15: Plumbing Repair Parts | B15: 1 | C15: lot | D15: 50 | E15: =B15*D15
A16: Door Lockset | B16: 1 | C16: each | D16: 35 | E16: =B16*D16
A17: Materials Subtotal (per room) | E17: =SUM(E5:E16) | F17: =E17*7
A19: LABOR - Light Renovation (per room)
A20: Task | B20: Hours | C20: Rate/Hr | D20: Unit Cost | E20: Extended | F20: Total
A21: Floor prep/sand/stain | B21: 8 | C21: 22 | E21: =B21*C21
A22: Paint (prep + 2 coats) | B22: 12 | C22: 22 | E22: =B22*C22
A23: Drywall repair | B23: 3 | C23: 22 | E23: =B23*C23
A24: Plumbing touchup | B24: 1 | C24: 22 | E24: =B24*C24
A25: Electrical | B25: 1 | C25: 22 | E25: =B25*C25
A26: Install hardware | B26: 0.5 | C26: 22 | E26: =B26*C26
A27: Labor Subtotal (per room) | E27: =SUM(E21:E26) | F27: =E27*7
A29: LIGHT RENOVATION TOTAL | E29: =E17+E27 | F29: =F17+F27
A32: FULL RENOVATION (36 rooms @ $8,273/room)
A33: Item | B33: Quantity | C33: Unit | D33: Unit Cost | E33: Extended | F33: Total
A34: Drywall 4x8 Sheet | B34: 19 | C34: sheet | D34: 13 | E34: =B34*D34
A35: Joint Compound | B35: 3 | C35: bucket | D35: 18 | E35: =B35*D35
A36: Drywall Tape | B36: 2 | C36: roll | D36: 7 | E36: =B36*D36
A37: Drywall Screws | B37: 1 | C37: box | D37: 15 | E37: =B37*D37
A38: Paint - Primer | B38: 2 | C38: gallon | D38: 35 | E38: =B38*D38
A39: Paint - Finish | B39: 4 | C39: gallon | D39: 45 | E39: =B39*D39
A40: Floor Sander Rental | B40: 0.33 | C40: day | D40: 90 | E40: =B40*D40
A41: Floor Stain | B41: 1.5 | C41: gallon | D41: 50 | E41: =B41*D41
A42: Polyurethane | B42: 1 | C42: gallon | D42: 60 | E42: =B42*D42
A43: Sandpaper/Supplies | B43: 1 | C43: lot | D43: 30 | E43: =B43*D43
A44: Bathroom Wall Tile | B44: 112 | C44: sqft | D44: 3.5 | E44: =B44*D44
A45: Bathroom Floor Tile | B45: 50 | C45: sqft | D45: 4 | E45: =B45*D45
...

Sheet Current Operations
A1: CURRENT OPERATIONS (April 2026)
A3: OPERATING PERFORMANCE
A4: Occupied Rooms: | B4: 18
A5: Available Rooms: | B5: 24
A6: Occupancy Rate: | B6: =B4/B5
A8: REVENUE
A9: Monthly Rent (Contractual): | B9: 15340
A10: Annualized Revenue: | B10: =B9*12
A12: OPERATING EXPENSES (Q1 2026 Average)
A13: Payroll | B13: 4792
A14: Property Taxes | B14: 3000
A15: Electric | B15: 960
A16: Gas | B16: 278
A17: Water | B17: 991
A18: Sewer | B18: 322
A19: Trash | B19: 110
A20: Consumables | B20: 1000
A21: Total Monthly Expenses: | B21: =SUM(B13:B20)
A22: Annual Operating Expenses: | B22: =B21*12
A24: NET OPERATING INCOME
A25: Annual NOI: | B25: =B10-B22

Sheet Historical Rent Roll
A1: HISTORICAL RENT ROLL - APRIL 2026
A3: Current Baseline Performance
A5: Room # | B5: Tenant Name | C5: Monthly Rent | D5: Status | E5: Notes
A6: 100 | B6: Joy | C6: 700 | D6: Occupied
A7: 101 | B7: Patrick Blasingme | C7: 700 | D7: Occupied
A8: 102 | B8: Jesus Carrion | C8: 700 | D8: Occupied
A9: 103 | B9: Rolando Benavides | C9: 700 | D9: Occupied
A10: 104 | B10: James Hruska | C10: 700 | D10: Occupied
A11: 105 | B11: Mollie Moses | C11: 700 | D11: Occupied
A12: 106 | B12: David Herrera and Laura? | C12: 700 | D12: Occupied
A13: 109 | B13: Dennis Garcia | C13: 640 | D13: Occupied
A14: 110 | B14: Rosendo Zuniga | C14: 640 | D14: Occupied
A15: 111 | B15: Christi Mcginis | C15: 640 | D15: Occupied
A16: 113 | B16: Luis Lira | C16: 640 | D16: Occupied
A17: 216 | B17: Richard Ramon | C17: 640 | D17: Occupied
... A23: 230 | B23: Angel Uribe | C23: 640 | D23: Occupied
A24: TOTAL OCCUPIED: | B24: 18
A25: TOTAL MONTHLY RENT: | C25: =SUM(C6:C23)

Sheet Renovation Schedule
A1: RENOVATION SCHEDULE - 6 MONTH TIMELINE
A3: Rooms to Renovate: 43 (7 light, 36 full)
A4: Average: 7.17 rooms per month
A6: Month | B6: Rooms Completed | C6: Cumulative Online | D6: Total Rooms Available | E6: Notes
A7: 0 | B7: 0 | C7: 0 | D7: 24 | E7: Baseline - 24 rooms currently available
A8: 1 | B8: 7 | C8: 7 | D8: 31 | E8: Begin renovation - light reno rooms prioritized
A9: 2 | B9: 7 | C9: 14 | D9: 38
A10: 3 | B10: 7 | C10: 21 | D10: 45 | E10: Halfway point
A11: 4 | B11: 7 | C11: 28 | D11: 52
A12: 5 | B12: 7 | C12: 35 | D12: 59
A13: 6 | B13: 7 | C13: 42 | D13: 66 | E13: Renovation complete - 67 rooms total
A14: POST-RENOVATION: | D14: 67 | E14: All rooms available

Sheet 10-Year Monthly Projections
A1: 10-YEAR MONTHLY CASH FLOW PROJECTIONS
A3: Year | B3: Mo | C3: Rooms Avail | D3: Occ % | E3: Avg Rent | F3: Room Revenue | G3: Laundry Rev | H3: Total Revenue | I3: Op Expenses | J3: NOI | K3: Debt Service | L3: Cash Flow | M3: DSCR
A4: 1 | B4: 1 | C4: 24 | D4: 0.5625 | E4: 852 | F4: =C4*D4*E4 | G4: ='Laundry Revenue'!I10 | H4: =F4+G4 | I4: =C4*344 | J4: =H4-I4 | K4: 6281.43 | L4: =J4-K4 | M4: =IF(K4=0,0,J4/K4)
A5: 1 | B5: 2 | C5: 31 | D5: 0.5625 | E5: 852 | F5: =C5*D5*E5 | G5: ='Laundry Revenue'!I11 | H5: =F5+G5 | I5: =C5*344 | J5: =H5-I5 | K5: 6281.43 | L5: =J5-K5 | M5: =IF(K5=0,0,J5/K5)
A6: 1 | B6: 3 | C6: 38 | D6: 0.5625 | E6: 852 | F6: =C6*D6*E6 | G6: ='Laundry Revenue'!I12 | H6: =F6+G6 | I6: =C6*344 | J6: =H6-I6 | K6: 6281.43 | L6: =J6-K6 | M6: =IF(K6=0,0,J6/K6)
A7: 1 | B7: 4 | C7: 46 | D7: 0.5625 | E7: 852 | F7: =C7*D7*E7 | G7: ='Laundry Revenue'!I13 | H7: =F7+G7 | I7: =C7*344 | J7: =H7-I7 | K7: 6281.43 | L7: =J7-K7 | M7: =IF(K7=0,0,J7/K7)
A8: 1 | B8: 5 | C8: 53 | D8: 0.5625 | E8: 852 | F8: =C8*D8*E8 | G8: ='Laundry Revenue'!I14 | H8: =F8+G8 | I8: =C8*344 | J8: =H8-I8 | K8: 6281.43 | L8: =J8-K8 | M8: =IF(K8=0,0,J8/K8)
A9: 1 | B9: 6 | C9: 60 | D9: 0.5625 | E9: 852 | F9: =C9*D9*E9 | G9: ='Laundry Revenue'!I15 | H9: =F9+G9 | I9: =C9*344 | J9: =H9-I9 | K9: 6281.43 | L9: =J9-K9 | M9: =IF(K9=0,0,J9/K9)
A10: 1 | B10: 7 | C10: 67 | D10: 0.7 | E10: 850 | F10: =C10*D10*E10 | G10: ='Laundry Revenue'!I16 | H10: =F10+G10 | I10: =C10*344 | J10: =H10-I10 | K10: 6281.43 | L10: =J10-K10 | M10: =IF(K10=0,0,J10/K10)
A11: 1 | B11: 8 | C11: 67 | D11: 0.70833 | E11: 850 | F11: =C11*D11*E11 | G11: ='Laundry Revenue'!I17 | H11: =F11+G11 | I11: =C11*344 | J11: =H11-I11 | K11: 6281.43 | L11: =J11-K11 | M11: =IF(K11=0,0,J11/K11)
A12: 1 | B12: 9 | C12: 67 | D12: 0.71666 | E12: 850 | F12: =C12*D12*E12 | G12: ='Laundry Revenue'!I18 | H12: =F12+G12 | I12: =C12*344 | J12: =H12-I12 | K12: 6281.43 | L12: =J12-K12 | M12: =IF(K12=0,0,J12/K12)
A13: 1 | B13: 10 | C13: 67 | D13: 0.72499 | E13: 850 | F13: =C13*D13*E13 | G13: ='Laundry Revenue'!I19 | H13: =F13+G13 | I13: =C13*344 | J13: =H13-I13 | K13: 6281.43 | L13: =J13-K13 | M13: =IF(K13=0,0,J13/K13)
A14: 1 | B14: 11 | C14: 67 | D14: 0.73332 | E14: 850 | F14: =C14*D14*E14 | G14: ='Laundry Revenue'!I20 | H14: =F14+G14 | I14: =C14*344 | J14: =H14-I14 | K14: 6281.43 | L14: =J14-K14 | M14: =IF(K14=0,0,J14/K14)
A15: 1 | B15: 12 | C15: 67 | D15: 0.74165 | E15: 850 | F15: =C15*D15*E15 | G15: ='Laundry Revenue'!I21 | H15: =F15+G15 | I15: =C15*344 | J15: =H15-I15 | K15: 6281.43 | L15: =J15-K15 | M15: =IF(K15=0,0,J15/K15)
... A123: 10 | B123: 12 | C123: 67 | D123: 0.8 | E123: 850 | F123: =C123*D123*E123 | G123: ='Laundry Revenue'!I129 | H123: =F123+G123 | I123: =C123*344 | J123: =H123-I123 | K123: 6281.43 | L123: =J123-K123 | M123: =IF(K123=0,0,J123/K123)

Sheet Annual Summary
A1: ANNUAL SUMMARY & KEY METRICS
A3: Year | B3: Gross Revenue | C3: Operating Expenses | D3: NOI | E3: Debt Service | F3: Net Cash Flow | G3: DSCR | H3: Cum Cash Flow
A4: 1 | B4: =SUM('10-Year Monthly Projections'!H4:H15) | C4: =SUM('10-Year Monthly Projections'!I4:I15) | D4: =B4-C4 | E4: =SUM('10-Year Monthly Projections'!K4:K15) | F4: =D4-E4 | G4: =IF(E4=0,0,D4/E4) | H4: =F4
A5: 2 | B5: =SUM('10-Year Monthly Projections'!H16:H27) | C5: =SUM('10-Year Monthly Projections'!I16:I27) | D5: =B5-C5 | E5: =SUM('10-Year Monthly Projections'!K16:K27) | F5: =D5-E5 | G5: =IF(E5=0,0,D5/E5) | H5: =H4+F5
A6: 3 | B6: =SUM('10-Year Monthly Projections'!H28:H39) | C6: =SUM('10-Year Monthly Projections'!I28:I39) | D6: =B6-C6 | E6: =SUM('10-Year Monthly Projections'!K28:K39) | F6: =D6-E6 | G6: =IF(E6=0,0,D6/E6) | H6: =H5+F6
A7: 4 | B7: =SUM('10-Year Monthly Projections'!H40:H51) | C7: =SUM('10-Year Monthly Projections'!I40:I51) | D7: =B7-C7 | E7: =SUM('10-Year Monthly Projections'!K40:K51) | F7: =D7-E7 | G7: =IF(E7=0,0,D7/E7) | H7: =H6+F7
A8: 5 | B8: =SUM('10-Year Monthly Projections'!H52:H63) | C8: =SUM('10-Year Monthly Projections'!I52:I63) | D8: =B8-C8 | E8: =SUM('10-Year Monthly Projections'!K52:K63) | F8: =D8-E8 | G8: =IF(E8=0,0,D8/E8) | H8: =H7+F8
A9: 6 | B9: =SUM('10-Year Monthly Projections'!H64:H75) | C9: =SUM('10-Year Monthly Projections'!I64:I75) | D9: =B9-C9 | E9: =SUM('10-Year Monthly Projections'!K64:K75) | F9: =D9-E9 | G9: =IF(E9=0,0,D9/E9) | H9: =H8+F9
A10: 7 | B10: =SUM('10-Year Monthly Projections'!H76:H87) | C10: =SUM('10-Year Monthly Projections'!I76:I87) | D10: =B10-C10 | E10: =SUM('10-Year Monthly Projections'!K76:K87) | F10: =D10-E10 | G10: =IF(E10=0,0,D10/E10) | H10: =H9+F10
A11: 8 | B11: =SUM('10-Year Monthly Projections'!H88:H99) | C11: =SUM('10-Year Monthly Projections'!I88:I99) | D11: =B11-C11 | E11: =SUM('10-Year Monthly Projections'!K88:K99) | F11: =D11-E11 | G11: =IF(E11=0,0,D11/E11) | H11: =H10+F11
A12: 9 | B12: =SUM('10-Year Monthly Projections'!H100:H111) | C12: =SUM('10-Year Monthly Projections'!I100:I111) | D12: =B12-C12 | E12: =SUM('10-Year Monthly Projections'!K100:K111) | F12: =D12-E12 | G12: =IF(E12=0,0,D12/E12) | H12: =H11+F12
A13: 10 | B13: =SUM('10-Year Monthly Projections'!H112:H123) | C13: =SUM('10-Year Monthly Projections'!I112:I123) | D13: =B13-C13 | E13: =SUM('10-Year Monthly Projections'!K112:K123) | F13: =D13-E13 | G13: =IF(E13=0,0,D13/E13) | H13: =H12+F13

Sheet Sources & Uses
A1: SOURCES & USES OF FUNDS
A3: SOURCES
A4: New Loan Proceeds | B4: 850000
A5: TOTAL SOURCES | B5: =B4
A7: USES
A8: Existing Debt Payoff | B8: 150000
A9: Renovation & Amenities | B9: ='Renovation Budget Detail'!E156
A10: Contingency (10%) | B10: ='Renovation Budget Detail'!E157
A11: TOTAL USES | B11: =SUM(B8:B10)
A12: TOTAL USES | B12: =SUM(B8:B11)
A13: Note: 40% renovation grant potential ($240k) available but not assumed in projections
A14: Note: 40% renovation grant potential ($240k) available but not assumed in projections

Sheet Debt Service Schedule
A1: DEBT SERVICE SCHEDULE (First 10 Years)
A2: Loan: $850,000 @ 7.5% for 25 years
A4: Year | B4: Month | C4: Payment | D4: Interest | E4: Principal | F4: Balance
A5: 1 | B5: 1 | C5: 6281.43 | D5: 5312.5 | E5: 968.93 | F5: 849031.07
A6: 1 | B6: 2 | C6: 6281.43 | D6: 5306.4442 | E6: 974.98581 | F6: 848056.08
A7: 1 | B7: 3 | C7: 6281.43 | D7: 5300.3505 | E7: 981.07947 | F7: 847075
A8: 1 | B8: 4 | C8: 6281.43 | D8: 5294.2188 | E8: 987.21122 | F8: 846087.79
A9: 1 | B9: 5 | C9: 6281.43 | D9: 5288.0487 | E9: 993.38129 | F9: 845094.41
A10: 1 | B10: 6 | C10: 6281.43 | D10: 5281.8401 | E10: 999.58992 | F10: 844094.82
A11: 1 | B11: 7 | C11: 6281.43 | D11: 5275.5926 | E11: 1005.8374 | F11: 843088.98
A12: 1 | B12: 8 | C12: 6281.43 | D12: 5269.3062 | E12: 1012.1238 | F12: 842076.86
A13: 1 | B13: 9 | C13: 6281.43 | D13: 5262.9804 | E13: 1018.4496 | F13: 841058.41
A14: 1 | B14: 10 | C14: 6281.43 | D14: 5256.6151 | E14: 1024.8149 | F14: 840033.6
A15: 1 | B15: 11 | C15: 6281.43 | D15: 5250.21 | E15: 1031.22 | F15: 839002.38
A16: 1 | B16: 12 | C16: 6281.43 | D16: 5243.7649 | E16: 1037.6651 | F16: 837964.71
... A124: 10 | B124: 12 | C124: 6281.43 | D124: 4247.698 | E124: 2033.732 | F124: 677597.95

Sheet Property Valuation
A1: PROPERTY VALUATION ANALYSIS
A3: CURRENT VALUE (AS-IS)
A4: Current NOI: | B4: ='Current Operations'!B25
A5: Capitalization Rate: | B5: 0.12
A6: Current Value: | B6: =B4/B5
A8: STABILIZED VALUE (Post-Renovation, Year 3)
A9: Stabilized NOI: | B9: ='Annual Summary'!D6
A10: Capitalization Rate: | B10: 0.1
A11: Stabilized Value: | B11: =B9/B10
A13: LOAN METRICS
A14: Loan Amount: | B14: 850000
A15: Stabilized Value: | B15: =B11
A16: Loan-to-Value (LTV): | B16: =B14/B15
A17: Equity Position: | B17: =B15-B14

Sheet Sensitivity Analysis
A1: SENSITIVITY ANALYSIS - DSCR SCENARIOS
A3: Year 3 Stabilized Performance Under Various Scenarios
A5: Scenario | B5: Occupancy | C5: Avg Rent | D5: Annual Revenue | E5: Annual Op Exp | F5: NOI | G5: Annual Debt Svc | H5: DSCR
A6: Conservative | B6: 0.7 | C6: 800 | D6: 461130.18 | E6: 276576 | F6: 184554.18 | G6: 75377 | H6: 2.448415
A7: Base Case | B7: 0.8 | C7: 850 | D7: 559165.92 | E7: 276576 | F7: 282589.92 | G7: 75377 | H7: 3.7490205
A8: Optimistic | B8: 0.9 | C8: 900 | D8: 665241.66 | E8: 276576 | F8: 388665.66 | G8: 75377 | H8: 5.1562898
A11: STRESS TEST SCENARIOS
A12: Scenario | B12: Occupancy | C12: Avg Rent | D12: DSCR | E12: Pass/Fail
A13: Severe Downturn | B13: 0.6 | C13: 750 | D13: 1.2544734 | E13: PASS
A14: Moderate Stress | B14: 0.65 | C14: 775 | D14: 1.8381112 | E14: PASS
A15: Mild Stress | B15: 0.7 | C15: 800 | D15: 2.448415 | E15: PASS

Sheet Assumptions & Notes
A1: ASSUMPTIONS & METHODOLOGY
A3: PROPERTY ASSUMPTIONS
A4: Total Rooms: | B4: 67 rooms (historic hotel capacity)
A5: Currently Available: | B5: 24 rooms (as of April 2026)
A6: Currently Occupied: | B6: 18 rooms (75% of available)
A7: To Be Renovated: | B7: 43 rooms (7 light, 36 full)
A8: Renovation Timeline: | B8: 6 months from loan closing
A10: REVENUE ASSUMPTIONS
A11: Average Rent: | B11: $850/month post-renovation (range: $700-$1,000)
A12: Current Rent: | B12: $640-$700/month (as of April 2026)
A13: Stabilized Occupancy: | B13: 80% (conservative for extended stay market)
A14: Ramp-Up Period: | B14: 12 months post-renovation to reach stabilized occupancy
A15: During Renovation Occupancy: | B15: 75% of current baseline maintained
A16: Laundry Revenue: | B16: 1.0 load per occupied room per week @ $4.50/load
A17: Laundry Equipment: | B17: 6 commercial washers, 6 dryers
A19: OPERATING EXPENSE ASSUMPTIONS
A20: Operating Expense per Room: | B20: $344/room/month (all-in)
A21: Includes: | B21: Payroll, property taxes, utilities, maintenance, insurance, supplies
A22: Basis: | B22: Q1 2026 actual expenses scaled to 67 rooms
A23: Payroll: | B23: $4,792/month average (Q1 2026)
A24: Property Taxes: | B24: $3,000/month ($36,000/year)
A25: Utilities: | B25: Electric, gas, water, sewer (~$2,300/month total)
A27: RENOVATION COST ASSUMPTIONS
A28: Light Renovation: | B28: $1,217/room × 7 rooms = $8,519
A29: Full Renovation: | B29: $8,273/room × 36 rooms = $297,828
A30: Central HVAC System: | B30: $32,000 (20-ton central unit, ductwork, dampers)
A31: Extended Laundry Facility: | B31: $47,100 (6 washers, 6 dryers, installation)
A32: Extended Kitchen: | B32: $37,500 (commercial equipment, installation)
A33: Infrastructure/Jobsite: | B33: $25,000 (permits, tools, management)
A34: Subtotal: | B34: $448,347
A35: Contingency: | B35: $44,835 (10%)
A36: Total Renovation Budget: | B36: $493,182
A38: LOAN ASSUMPTIONS
A39: Loan Amount: | B39: $850,000 (cash-out refinance)
A40: Use of Proceeds: | B40: $150k debt payoff + $493k renovation + $207k cushion
A41: Interest Rate: | B41: 7.5% (30-year commercial mortgage rate)
A42: Amortization: | B42: 25 years
A43: Monthly Payment: | B43: $6,281.43 (principal + interest)
A44: Annual Debt Service: | B44: $75,377
A45: Existing Debt: | B45: $141,000 (to be paid off at closing)
...

Sheet Laundry Revenue
A1: LAUNDRY REVENUE PROJECTIONS (120 Months)
A3: ASSUMPTIONS:
A4: Loads per occupied room per week: | B4: 1
A5: Washer price per load: | B5: 2.5
A6: Dryer price per load: | B6: 2
A7: Total per load: | B7: =B5+B6
A9: Year | B9: Month | C9: Rooms Avail | D9: Occ % | E9: Occupied | F9: Weekly Loads | G9: Monthly Loads | H9: Price/Load | I9: Monthly Revenue | J9: Monthly Revenue
A10: 1 | B10: 1 | C10: 24 | D10: 0.5625 | E10: =C10*D10 | F10: =E10*$B$4 | G10: =F10*4.3 | H10: =$B$7 | I10: =G10*H10 | J10: =E10*F10
A11: 1 | B11: 2 | C11: 31 | D11: 0.5625 | E11: =C11*D11 | F11: =E11*$B$4 | G11: =F11*4.3 | H11: =$B$7 | I11: =G11*H11 | J11: =E11*F11
A12: 1 | B12: 3 | C12: 38 | D12: 0.5625 | E12: =C12*D12 | F12: =E12*$B$4 | G12: =F12*4.3 | H12: =$B$7 | I12: =G12*H12 | J12: =E12*F12
A13: 1 | B13: 4 | C13: 46 | D13: 0.5625 | E13: =C13*D13 | F13: =E13*$B$4 | G13: =F13*4.3 | H13: =$B$7 | I13: =G13*H13 | J13: =E13*F13
A14: 1 | B14: 5 | C14: 53 | D14: 0.5625 | E14: =C14*D14 | F14: =E14*$B$4 | G14: =F14*4.3 | H14: =$B$7 | I14: =G14*H14 | J14: =E14*F14
A15: 1 | B15: 6 | C15: 60 | D15: 0.5625 | E15: =C15*D15 | F15: =E15*$B$4 | G15: =F15*4.3 | H15: =$B$7 | I15: =G15*H15 | J15: =E15*F15
A16: 1 | B16: 7 | C16: 67 | D16: 0.7 | E16: =C16*D16 | F16: =E16*$B$4 | G16: =F16*4.3 | H16: =$B$7 | I16: =G16*H16 | J16: =E16*F16
A17: 1 | B17: 8 | C17: 67 | D17: 0.70833 | E17: =C17*D17 | F17: =E17*$B$4 | G17: =F17*4.3 | H17: =$B$7 | I17: =G17*H17 | J17: =E17*F17
A18: 1 | B18: 9 | C18: 67 | D18: 0.71666 | E18: =C18*D18 | F18: =E18*$B$4 | G18: =F18*4.3 | H18: =$B$7 | I18: =G18*H18 | J18: =E18*F18
A19: 1 | B19: 10 | C19: 67 | D19: 0.72499 | E19: =C19*D19 | F19: =E19*$B$4 | G19: =F19*4.3 | H19: =$B$7 | I19: =G19*H19 | J19: =E19*F19
A20: 1 | B20: 11 | C20: 67 | D20: 0.73332 | E20: =C20*D20 | F20: =E20*$B$4 | G20: =F20*4.3 | H20: =$B$7 | I20: =G20*H20 | J20: =E20*F20
A21: 1 | B21: 12 | C21: 67 | D21: 0.74165 | E21: =C21*D21 | F21: =E21*$B$4 | G21: =F21*4.3 | H21: =$B$7 | I21: =G21*H21 | J21: =E21*F21
... A129: 10 | B129: 12 | C129: 67 | D129: 0.8 | E129: =C129*D129 | F129: =E129*$B$4 | G129: =F129*4.3 | H129: =$B$7 | I129: =G129*H129 | J129: =E129*F129
